Workbook

Sheet characterization & setup
A1: sunflower
B2: air dried | C2: 105℃ corrected
A3: Bulk density (g/cm3) | B3: 1.103 | C3: =$G$22*B3 -> 1.0666894
A4: particle density (g/cm3) | B4: 2.206 | C4: =B4 -> 2.206
A5: porosity | B5: =(100-(B3/B4)*100) -> 50 | C5: =(100-(C3/C4)*100) -> 51.645994
A6: gWater/gAirdriedsoil | B6: =$H$21 -> 0.034050691
A7: %saturation of air-dried soil | B7: =$I$21 -> 7.5115825
A8: soil texture
A9: soil type | B9: silty clay
A10: pH | B10: 5
A11: LOI% | B11: =$L$21 -> 5.9836626
A12: SOC% | B12: =0.58*B11 -> 3.4705243
A14: sunflower
A15: Water Content and Organic Matter% of Air-dried Soil
A16: replicate | B16: Can+lid (g) | C16: Can+lid+soil (g) | D16: soil wt (g) before drying | E16: can+lid+soil weight post 105℃ (g) | F16: H2O lost (g) | G16: soil weight post 105℃ (g) | H16: GM (gH2O/g105C dried soil) | I16: %sat of air dried soil | J16: can+lid+soil weight post 505℃ (g) | K16: OM lost (g) | L16: LOI%
A17: 1 | B17: 10.0333 | C17: 11.0147 | D17: =C17-B17 -> 0.9814 | E17: 10.9813 | F17: =C17-E17 -> 0.0334 | G17: =D17-F17 -> 0.948 | H17: =F17/G17 -> 0.035232068 | I17: =100*H17*$B$3/($B$5*0.01) -> 7.7721941 | J17: 10.9246 | K17: =E17-J17 -> 0.0567 | L17: =100*K17/G17 -> 5.9810127
A18: 2 | B18: 10.3336 | C18: 11.3803 | D18: =C18-B18 -> 1.0467 | E18: 11.3453 | F18: =C18-E18 -> 0.035 | G18: =D18-F18 -> 1.0117 | H18: =F18/G18 -> 0.034595236 | I18: =100*H18*$B$3/($B$5*0.01) -> 7.631709 | J18: 11.2857 | K18: =E18-J18 -> 0.0596 | L18: =100*K18/G18 -> 5.8910744
A19: 3 | B19: 10.961 | C19: 11.954 | D19: =C19-B19 -> 0.993 | E19: 11.9217 | F19: =C19-E19 -> 0.0323 | G19: =D19-F19 -> 0.9607 | H19: =F19/G19 -> 0.033621318 | I19: =100*H19*$B$3/($B$5*0.01) -> 7.4168627 | J19: 11.8633 | K19: =E19-J19 -> 0.0584 | L19: =100*K19/G19 -> 6.0789008
A20: 4 | B20: 10.0447 | C20: 11.0789 | D20: =C20-B20 -> 1.0342 | E20: 11.0461 | F20: =C20-E20 -> 0.0328 | G20: =D20-F20 -> 1.0014 | H20: =F20/G20 -> 0.032754144 | I20: =100*H20*$B$3/($B$5*0.01) -> 7.2255642 | J20: 10.9874 | K20: =E20-J20 -> 0.0587 | L20: =100*K20/G20 -> 5.8617935
A21: average | D21: =AVERAGE(D17:D20) -> 1.013825 | G21: =AVERAGE(G17:G20) -> 0.98045 | H21: =AVERAGE(H17:H20) -> 0.034050691 | I21: =AVERAGE(I17:I20) -> 7.5115825 | L21: =AVERAGE(L17:L19) -> 5.9836626
F22: m105/mair-dried | G22: =G21/D21 -> 0.96708012
A24: Soil Moisture Amendment Calculations
A25: porosity | B25: 0.5
A26: grams of water needed per gram of soil=target moisture% * porosity of soil
A28: Target %S | B28: gWater needed per gSoil | C28: gSoil in experiment | D28: uL water already in soil | E28: uL water to add | F28: 1g water~1mL
A29: 7 | B29: =A29*$B$25*0.01 -> 0.035 | C29: 2 | D29: =$H$21*C29*1000 -> 68.101383 | E29: =B29*C29*1000-D29 -> 1.8986174
A30: 8 | B30: =A30*$B$25*0.01 -> 0.04 | C30: 2 | D30: =$H$21*C30*1000 -> 68.101383 | E30: =B30*C30*1000-D30 -> 11.898617
A31: 9 | B31: =A31*$B$25*0.01 -> 0.045 | C31: 2 | D31: =$H$21*C31*1000 -> 68.101383 | E31: =B31*C31*1000-D31 -> 21.898617
A32: 10 | B32: =A32*$B$25*0.01 -> 0.05 | C32: 2 | D32: =$H$21*C32*1000 -> 68.101383 | E32: =B32*C32*1000-D32 -> 31.898617
A33: 15 | B33: =A33*$B$25*0.01 -> 0.075 | C33: 2 | D33: =$H$21*C33*1000 -> 68.101383 | E33: =B33*C33*1000-D33 -> 81.898617
A34: 20 | B34: =A34*$B$25*0.01 -> 0.1 | C34: 2 | D34: =$H$21*C34*1000 -> 68.101383 | E34: =B34*C34*1000-D34 -> 131.89862
A35: 25 | B35: =A35*$B$25*0.01 -> 0.125 | C35: 2 | D35: =$H$21*C35*1000 -> 68.101383 | E35: =B35*C35*1000-D35 -> 181.89862
A36: 30 | B36: =A36*$B$25*0.01 -> 0.15 | C36: 2 | D36: =$H$21*C36*1000 -> 68.101383 | E36: =B36*C36*1000-D36 -> 231.89862
A37: 40 | B37: =A37*$B$25*0.01 -> 0.2 | C37: 2 | D37: =$H$21*C37*1000 -> 68.101383 | E37: =B37*C37*1000-D37 -> 331.89862
A38: 10 | B38: =A38*$B$25*0.01 -> 0.05 | C38: 3 | D38: =$H$21*C38*1000 -> 102.15207 | E38: =B38*C38*1000-D38 -> 47.847926
A39: 20 | B39: =A39*$B$25*0.01 -> 0.1 | C39: 3 | D39: =$H$21*C39*1000 -> 102.15207 | E39: =B39*C39*1000-D39 -> 197.84793
A41: back calculation of target %S from volume of water added
A42: =B42*100/$B$25 -> 14.310138 | B42: =(E42+D42)/(C42*1000) -> 0.071550691 | C42: 2 | D42: =$H$21*C42*1000 -> 68.101383 | E42: 75
A43: =B43*100/$B$25 -> 21.310138 | B43: =(E43+D43)/(C43*1000) -> 0.10655069 | C43: 2 | D43: =$H$21*C43*1000 -> 68.101383 | E43: 145
A47: corn
...

Sheet H2 uptake rates
A1: sampling Time | B1: Time diff | C1: Time diff (number) | D1: time point | E1: time (min) | F1: injection time | G1: dilution vol (mL) | H1: H2 area | I1: H2 ppm, calculated | J1: dilution corrected | K1: Comments | L1: Natural Log (ln) - linear | M1: Slope (k) | N1: Baselined | O1: LinEst to Air | Q1: LinEst Floating | S1: Abs(Air M) | T1: Linest Floating - Abbreviated | V1: Abs(All Data M/grams SOC | W1: Abs(Brev Float M)/grams SOC
A2: measured FGF sunflower and corn soils, 22℃, 20%, 2g of soil per bottle,acclimated overnight, measured on , used lab air as dilution gas
A3: FGF-sf-20-1 | V3: Tails | W3: No Tails
B4: 0.091666667 | C4: =HOUR(B4)*60+MINUTE(B4) -> 132 | D4: 0 | E4: {=C4-INDIRECT("C" & (ROW(D4) - D4))} -> 0 | G4: 2 | H4: 276315 | I4: =H4/506515 -> 0.54552185 | J4: =(I4*240-$C$325*2)/238 -> 0.54525533 | L4: =LN(J4) -> -0.6065011 | M4: =SLOPE(L4:L13, E4:E13) -> -0.0070754474 | N4: {=L4-INDIRECT("L" & (ROW(L4)-D4))} -> 0 | O4: {=LINEST(_xlfn._xlws.FILTER(N4:N15,NOT(ISBLANK(N4:N15))),_xlfn._xlws.FILTER(E4:E15,NOT(ISBLANK(E4:E15))), FALSE, TRUE)} -> -0.0075743019 | P4: 0 | Q4: {=LINEST(_xlfn._xlws.FILTER(N4:N15, NOT(ISBLANK(N4:N15))),_xlfn._xlws.FILTER(E4:E15, NOT(ISBLANK(E4:E15))), TRUE, TRUE)} -> -0.0070754474 | R4: -0.079728171 | S4: =ABS(O4) -> 0.0075743019 | T4: {=LINEST(_xlfn._xlws.FILTER(N4:N8, NOT(ISBLANK(N4:N8))),_xlfn._xlws.FILTER(E4:E8, NOT(ISBLANK(E4:E8))), TRUE, TRUE)} -> -0.0076919767 | U4: -0.041394631 | V4: =S4/(2*'characterization & setup'!$B$12/100) -> 0.10912331 | W4: =ABS(T4)/(2*'characterization & setup'!$B$12/100) -> 0.11081865
B5: 0.097916667 | C5: =HOUR(B5)*60+MINUTE(B5) -> 141 | D5: 1 | E5: {=C5-INDIRECT("C" & (ROW(D5) - D5))} -> 9 | G5: 2 | H5: 221635 | I5: =H5/506515 -> 0.43756848 | J5: =(I5*240-$C$325*2)/238 -> 0.43639479 | L5: =LN(J5) -> -0.82920796 | N5: {=L5-INDIRECT("L" & (ROW(L5)-D5))} -> -0.22270686 | O5: 0.00030983236 | P5: #N/A | Q5: 0.00044966026 | R5: 0.054643621 | T5: 0.0016774908 | U5: 0.058472046
B6: 0.10763889 | C6: =HOUR(B6)*60+MINUTE(B6) -> 155 | D6: 2 | E6: {=C6-INDIRECT("C" & (ROW(D6) - D6))} -> 23 | F6: * | G6: 2 | H6: 241592 | I6: =H6/506515 -> 0.47696909 | J6: =(I6*240-$C$325*2)/238 -> 0.4761265 | L6: =LN(J6) -> -0.74207171 | N6: {=L6-INDIRECT("L" & (ROW(L6)-D6))} -> -0.13557061 | O6: 0.98516391 | P6: 0.11906435 | Q6: 0.96870027 | R6: 0.11223362 | T6: 0.87513501 | U6: 0.084496262
B7: 0.11736111 | C7: =HOUR(B7)*60+MINUTE(B7) -> 169 | D7: 3 | E7: {=C7-INDIRECT("C" & (ROW(D7) - D7))} -> 37 | G7: 2 | H7: 201027 | I7: =H7/506515 -> 0.39688262 | J7: =(I7*240-$C$325*2)/238 -> 0.39536703 | L7: =LN(J7) -> -0.92794076 | N7: {=L7-INDIRECT("L" & (ROW(L7)-D7))} -> -0.32143966 | O7: 597.62902 | P7: 9 | Q7: 247.59325 | R7: 8 | T7: 21.02595 | U7: 3
B8: 0.13611111 | C8: =HOUR(B8)*60+MINUTE(B8) -> 196 | D8: 4 | E8: {=C8-INDIRECT("C" & (ROW(D8) - D8))} -> 64 | G8: 2 | H8: 160405 | I8: =H8/506515 -> 0.31668361 | J8: =(I8*240-$C$325*2)/238 -> 0.31449408 | L8: =LN(J8) -> -1.15679 | N8: {=L8-INDIRECT("L" & (ROW(L8)-D8))} -> -0.55028892 | O8: 8.4721793 | P8: 0.12758687 | Q8: 3.1187798 | R8: 0.10077108 | T8: 0.15011726 | U8: 0.021418855
B9: 0.15138889 | C9: =HOUR(B9)*60+MINUTE(B9) -> 218 | D9: 5 | E9: {=C9-INDIRECT("C" & (ROW(D9) - D9))} -> 86 | G9: 2 | H9: 112837 | I9: =H9/506515 -> 0.22277129 | J9: =(I9*240-$C$325*2)/238 -> 0.21979258 | L9: =LN(J9) -> -1.515071 | N9: {=L9-INDIRECT("L" & (ROW(L9)-D9))} -> -0.9085699
B10: 0.17222222 | C10: =HOUR(B10)*60+MINUTE(B10) -> 248 | D10: 6 | E10: {=C10-INDIRECT("C" & (ROW(D10) - D10))} -> 116 | G10: 2 | H10: 107633 | I10: =H10/506515 -> 0.21249716 | J10: =(I10*240-$C$325*2)/238 -> 0.20943211 | L10: =LN(J10) -> -1.5633556 | N10: {=L10-INDIRECT("L" & (ROW(L10)-D10))} -> -0.95685453
B11: 0.19375 | C11: =HOUR(B11)*60+MINUTE(B11) -> 279 | D11: 7 | E11: {=C11-INDIRECT("C" & (ROW(D11) - D11))} -> 147 | G11: 2 | H11: 104459 | I11: =H11/506515 -> 0.20623081 | J11: =(I11*240-$C$325*2)/238 -> 0.20311311 | L11: =LN(J11) -> -1.5939923 | N11: {=L11-INDIRECT("L" & (ROW(L11)-D11))} -> -0.98749118
B12: 0.22638889 | C12: =HOUR(B12)*60+MINUTE(B12) -> 326 | D12: 8 | E12: {=C12-INDIRECT("C" & (ROW(D12) - D12))} -> 194 | G12: 2 | H12: 71365 | I12: =H12/506515 -> 0.14089415 | J12: =(I12*240-$C$325*2)/238 -> 0.13722739 | L12: =LN(J12) -> -1.9861159 | N12: {=L12-INDIRECT("L" & (ROW(L12)-D12))} -> -1.3796148
B13: 0.26388889 | C13: =HOUR(B13)*60+MINUTE(B13) -> 380 | D13: 9 | E13: {=C13-INDIRECT("C" & (ROW(D13) - D13))} -> 248 | G13: 2 | H13: 44544 | I13: =H13/506515 -> 0.087942114 | J13: =(I13*240-$C$325*2)/238 -> 0.083830385 | L13: =LN(J13) -> -2.4789598 | N13: {=L13-INDIRECT("L" & (ROW(L13)-D13))} -> -1.8724586
A16: FGF-sf-20-2
B17: 0.093055556 | C17: =HOUR(B17)*60+MINUTE(B17) -> 134 | D17: 0 | E17: {=C17-INDIRECT("C" & (ROW(D17) - D17))} -> 0 | G17: 0 | H17: 212143 | I17: =H17/506515 -> 0.41882866 | J17: =(I17*240-$C$325*2)/238 -> 0.41749749 | L17: =LN(J17) -> -0.87347674 | M17: =SLOPE(L17:L26, E17:E26) -> -0.0069339091 | N17: {=L17-INDIRECT("L" & (ROW(L17)-D17))} -> 0 | O17: {=LINEST(_xlfn._xlws.FILTER(N17:N28,NOT(ISBLANK(N17:N28))),_xlfn._xlws.FILTER(E17:E28,NOT(ISBLANK(E17:E28))), FALSE, TRUE)} -> -0.0060623948 | P17: 0 | Q17: {=LINEST(_xlfn._xlws.FILTER(N17:N28, NOT(ISBLANK(N17:N28))),_xlfn._xlws.FILTER(E17:E28, NOT(ISBLANK(E17:E28))), TRUE, TRUE)} -> -0.0069339091 | R17: 0.14139123 | S17: =ABS(O17) -> 0.0060623948 | T17: {=LINEST(_xlfn._xlws.FILTER(N17:N21, NOT(ISBLANK(N17:N21))),_xlfn._xlws.FILTER(E17:E21, NOT(ISBLANK(E17:E21))), TRUE, TRUE)} -> -0.0053154392 | U17: 0.073912147 | V17: =S17/(2*'characterization & setup'!$B$12/100) -> 0.087341195 | W17: =ABS(T17)/(2*'characterization & setup'!$B$12/100) -> 0.076579771
B18: 0.099305556 | C18: =HOUR(B18)*60+MINUTE(B18) -> 143 | D18: 1 | E18: {=C18-INDIRECT("C" & (ROW(D18) - D18))} -> 9 | G18: 2 | H18: 234063 | I18: =H18/506515 -> 0.46210477 | J18: =(I18*240-$C$325*2)/238 -> 0.46113727 | L18: =LN(J18) -> -0.77405952 | N18: {=L18-INDIRECT("L" & (ROW(L18)-D18))} -> 0.099417225 | O18: 0.00044888014 | P18: #N/A | Q18: 0.0006445621 | R18: 0.08177927 | T18: 0.0015806149 | U18: 0.057784391
B19: 0.10833333 | C19: =HOUR(B19)*60+MINUTE(B19) -> 156 | D19: 2 | F19: * | G19: 2 | O19: 0.95798346 | P19: 0.17085595 | Q19: 0.94296185 | R19: 0.15290061 | T19: 0.84972633 | U19: 0.077916457
B20: 0.11805556 | C20: =HOUR(B20)*60+MINUTE(B20) -> 170 | D20: 3 | E20: {=C20-INDIRECT("C" & (ROW(D20) - D20))} -> 36 | G20: 2 | H20: 193774 | I20: =H20/506515 -> 0.3825632 | J20: =(I20*240-$C$325*2)/238 -> 0.38092728 | L20: =LN(J20) -> -0.96514679 | N20: {=L20-INDIRECT("L" & (ROW(L20)-D20))} -> -0.091670048 | O20: 182.40119 | P20: 8 | Q20: 115.72489 | R20: 7 | T20: 11.309051 | U20: 2
B21: 0.13680556 | C21: =HOUR(B21)*60+MINUTE(B21) -> 197 | D21: 4 | E21: {=C21-INDIRECT("C" & (ROW(D21) - D21))} -> 63 | G21: 2 | H21: 159955 | I21: =H21/506515 -> 0.31579519 | J21: =(I21*240-$C$325*2)/238 -> 0.31359819 | L21: =LN(J21) -> -1.1596428 | N21: {=L21-INDIRECT("L" & (ROW(L21)-D21))} -> -0.28616602 | O21: 5.324611 | P21: 0.23353405 | Q21: 2.7054855 | R21: 0.16365018 | T21: 0.068656961 | U21: 0.012141949
B22: 0.15208333 | C22: =HOUR(B22)*60+MINUTE(B22) -> 219 | D22: 5 | E22: {=C22-INDIRECT("C" & (ROW(D22) - D22))} -> 85 | G22: 2 | H22: 133331 | I22: =H22/506515 -> 0.26323209 | J22: =(I22*240-$C$325*2)/238 -> 0.26059338 | L22: =LN(J22) -> -1.344794 | N22: {=L22-INDIRECT("L" & (ROW(L22)-D22))} -> -0.47131727
B23: 0.17291667 | C23: =HOUR(B23)*60+MINUTE(B23) -> 249 | D23: 6 | E23: {=C23-INDIRECT("C" & (ROW(D23) - D23))} -> 115 | G23: 2 | H23: 116467 | I23: =H23/506515 -> 0.22993791 | J23: =(I23*240-$C$325*2)/238 -> 0.22701942 | L23: =LN(J23) -> -1.4827197 | N23: {=L23-INDIRECT("L" & (ROW(L23)-D23))} -> -0.60924297
B24: 0.19444444 | C24: =HOUR(B24)*60+MINUTE(B24) -> 280 | D24: 7 | E24: {=C24-INDIRECT("C" & (ROW(D24) - D24))} -> 146 | G24: 2 | H24: 98887 | I24: =H24/506515 -> 0.19523015 | J24: =(I24*240-$C$325*2)/238 -> 0.19202 | L24: =LN(J24) -> -1.6501557 | N24: {=L24-INDIRECT("L" & (ROW(L24)-D24))} -> -0.776679
B25: 0.22708333 | C25: =HOUR(B25)*60+MINUTE(B25) -> 327 | D25: 8 | E25: {=C25-INDIRECT("C" & (ROW(D25) - D25))} -> 193 | G25: 2 | H25: 83359 | I25: =H25/506515 -> 0.16457361 | J25: =(I25*240-$C$325*2)/238 -> 0.16110584 | L25: =LN(J25) -> -1.8256937 | N25: {=L25-INDIRECT("L" & (ROW(L25)-D25))} -> -0.95221701
B26: 0.26388889 | C26: =HOUR(B26)*60+MINUTE(B26) -> 380 | D26: 9 | E26: {=C26-INDIRECT("C" & (ROW(D26) - D26))} -> 246 | G26: 2 | H26: 36023 | I26: =H26/506515 -> 0.071119315 | J26: =(I26*240-$C$325*2)/238 -> 0.066866218 | L26: =LN(J26) -> -2.7050614 | N26: {=L26-INDIRECT("L" & (ROW(L26)-D26))} -> -1.8315847
A29: FGF-sf-20-3
B30: 0.094444444 | C30: =HOUR(B30)*60+MINUTE(B30) -> 136 | D30: 0 | E30: {=C30-INDIRECT("C" & (ROW(D30) - D30))} -> 0 | G30: 0 | H30: 231078 | I30: =H30/506515 -> 0.45621156 | J30: =(I30*240-$C$325*2)/238 -> 0.45519454 | L30: =LN(J30) -> -0.7870304 | M30: =SLOPE(L30:L39, E30:E39) -> -0.0074846922 | N30: {=L30-INDIRECT("L" & (ROW(L30)-D30))} -> 0 | O30: {=LINEST(_xlfn._xlws.FILTER(N30:N41,NOT(ISBLANK(N30:N41))),_xlfn._xlws.FILTER(E30:E41,NOT(ISBLANK(E30:E41))), FALSE, TRUE)} -> -0.0074143161 | P30: 0 | Q30: {=LINEST(_xlfn._xlws.FILTER(N30:N41, NOT(ISBLANK(N30:N41))),_xlfn._xlws.FILTER(E30:E41, NOT(ISBLANK(E30:E41))), TRUE, TRUE)} -> -0.0074846922 | R30: 0.011299881 | S30: =ABS(O30) -> 0.0074143161 | T30: {=LINEST(_xlfn._xlws.FILTER(N30:N34, NOT(ISBLANK(N30:N34))),_xlfn._xlws.FILTER(E30:E34, NOT(ISBLANK(E30:E34))), TRUE, TRUE)} -> -0.0056041337 | U30: -0.071742662 | V30: =S30/(2*'characterization & setup'!$B$12/100) -> 0.10681839 | W30: =ABS(T30)/(2*'characterization & setup'!$B$12/100) -> 0.080739006
B31: 0.10138889 | C31: =HOUR(B31)*60+MINUTE(B31) -> 146 | D31: 1 | E31: {=C31-INDIRECT("C" & (ROW(D31) - D31))} -> 10 | G31: 2 | H31: 189147 | I31: =H31/506515 -> 0.37342823 | J31: =(I31*240-$C$325*2)/238 -> 0.37171554 | L31: =LN(J31) -> -0.98962638 | N31: {=L31-INDIRECT("L" & (ROW(L31)-D31))} -> -0.20259598 | O31: 0.00038078391 | P31: #N/A | Q31: 0.00065066339 | R31: 0.08157317 | T31: 0.0016251582 | U31: 0.057721721
B32: 0.10902778 | C32: =HOUR(B32)*60+MINUTE(B32) -> 157 | D32: 2 | F32: * | G32: 2 | O32: 0.97933496 | P32: 0.14321576 | Q32: 0.94975702 | R32: 0.15289467 | T32: 0.85602396 | U32: 0.076865001
B33: 0.11875 | C33: =HOUR(B33)*60+MINUTE(B33) -> 171 | D33: 3 | E33: {=C33-INDIRECT("C" & (ROW(D33) - D33))} -> 35 | G33: 2 | H33: 173613 | I33: =H33/506515 -> 0.34275984 | J33: =(I33*240-$C$325*2)/238 -> 0.34078944 | L33: =LN(J33) -> -1.0764905 | N33: {=L33-INDIRECT("L" & (ROW(L33)-D33))} -> -0.28946008 | O33: 379.12726 | P33: 8 | Q33: 132.32294 | R33: 7 | T33: 11.8912 | U33: 2
B34: 0.13680556 | C34: =HOUR(B34)*60+MINUTE(B34) -> 197 | D34: 4 | E34: {=C34-INDIRECT("C" & (ROW(D34) - D34))} -> 61 | G34: 2 | H34: 157402 | I34: =H34/506515 -> 0.31075486 | J34: =(I34*240-$C$325*2)/238 -> 0.30851551 | L34: =LN(J34) -> -1.1759832 | N34: {=L34-INDIRECT("L" & (ROW(L34)-D34))} -> -0.38895276 | O34: 7.776186 | P34: 0.16408603 | Q34: 3.0932842 | R34: 0.16363746 | T34: 0.070255926 | U34: 0.011816457
B35: 0.15208333 | C35: =HOUR(B35)*60+MINUTE(B35) -> 219 | D35: 5 | E35: {=C35-INDIRECT("C" & (ROW(D35) - D35))} -> 83 | G35: 2 | H35: 122281 | I35: =H35/506515 -> 0.24141635 | J35: =(I35*240-$C$325*2)/238 -> 0.23859431 | L35: =LN(J35) -> -1.4329906 | N35: {=L35-INDIRECT("L" & (ROW(L35)-D35))} -> -0.64596019
B36: 0.17291667 | C36: =HOUR(B36)*60+MINUTE(B36) -> 249 | D36: 6 | E36: {=C36-INDIRECT("C" & (ROW(D36) - D36))} -> 113 | G36: 2 | H36: 115447 | I36: =H36/506515 -> 0.22792415 | J36: =(I36*240-$C$325*2)/238 -> 0.22498874 | L36: =LN(J36) -> -1.4917049 | N36: {=L36-INDIRECT("L" & (ROW(L36)-D36))} -> -0.70467453
B37: 0.19444444 | C37: =HOUR(B37)*60+MINUTE(B37) -> 280 | D37: 7 | E37: {=C37-INDIRECT("C" & (ROW(D37) - D37))} -> 144 | G37: 2 | H37: 91128 | I37: =H37/506515 -> 0.17991175 | J37: =(I37*240-$C$325*2)/238 -> 0.17657287 | L37: =LN(J37) -> -1.7340216 | N37: {=L37-INDIRECT("L" & (ROW(L37)-D37))} -> -0.9469912
B38: 0.22708333 | C38: =HOUR(B38)*60+MINUTE(B38) -> 327 | D38: 8 | E38: {=C38-INDIRECT("C" & (ROW(D38) - D38))} -> 191 | G38: 2 | H38: 69224 | I38: =H38/506515 -> 0.13666723 | J38: =(I38*240-$C$325*2)/238 -> 0.13296495 | L38: =LN(J38) -> -2.0176697 | N38: {=L38-INDIRECT("L" & (ROW(L38)-D38))} -> -1.2306393
B39: 0.26388889 | C39: =HOUR(B39)*60+MINUTE(B39) -> 380 | D39: 9 | E39: {=C39-INDIRECT("C" & (ROW(D39) - D39))} -> 244 | G39: 2 | H39: 30914 | I39: =H39/506515 -> 0.061032743 | J39: =(I39*240-$C$325*2)/238 -> 0.056694885 | L39: =LN(J39) -> -2.8700713 | N39: {=L39-INDIRECT("L" & (ROW(L39)-D39))} -> -2.0830409
A42: FGF-co-20-1
B43: 0.096527778 | C43: =HOUR(B43)*60+MINUTE(B43) -> 139 | D43: 0 | E43: {=C43-INDIRECT("C" & (ROW(D43) - D43))} -> 0 | G43: 0 | H43: 197230 | I43: =H43/506515 -> 0.3893863 | J43: =(I43*240-$C$325*2)/238 -> 0.38780771 | L43: =LN(J43) -> -0.94724565 | M43: =SLOPE(L43:L52, E43:E52) -> -0.0062166 | N43: {=L43-INDIRECT("L" & (ROW(L43)-D43))} -> 0 | O43: {=LINEST(_xlfn._xlws.FILTER(N43:N54,NOT(ISBLANK(N43:N54))),_xlfn._xlws.FILTER(E43:E54,NOT(ISBLANK(E43:E54))), FALSE, TRUE)} -> -0.0055938889 | P43: 0 | Q43: {=LINEST(_xlfn._xlws.FILTER(N43:N54, NOT(ISBLANK(N43:N54))),_xlfn._xlws.FILTER(E43:E54, NOT(ISBLANK(E43:E54))), TRUE, TRUE)} -> -0.0062166 | R43: 0.1037363 | S43: =ABS(O43) -> 0.0055938889 | T43: {=LINEST(_xlfn._xlws.FILTER(N43:N47, NOT(ISBLANK(N43:N47))),_xlfn._xlws.FILTER(E43:E47, NOT(ISBLANK(E43:E47))), TRUE, TRUE)} -> -0.0019994209 | U43: 0.082100379 | V43: =S43/(2*'characterization & setup'!$B$59/100) -> 0.081312489 | W43: =ABS(T43)/(2*'characterization & setup'!$B$59/100) -> 0.029063483
B44: 0.10208333 | C44: =HOUR(B44)*60+MINUTE(B44) -> 147 | D44: 1 | E44: {=C44-INDIRECT("C" & (ROW(D44) - D44))} -> 8 | G44: 2 | H44: 233349 | I44: =H44/506515 -> 0.46069514 | J44: =(I44*240-$C$325*2)/238 -> 0.45971579 | L44: =LN(J44) -> -0.77714683 | N44: {=L44-INDIRECT("L" & (ROW(L44)-D44))} -> 0.17009883 | O44: 0.00034216885 | P44: #N/A | Q44: 0.00049267231 | R44: 0.064024421 | T44: 0.0047400676 | U44: 0.1062734
B45: 0.11180556 | C45: =HOUR(B45)*60+MINUTE(B45) -> 161 | D45: 2 | F45: * | G45: 2 | O45: 0.97447751 | P45: 0.12576881 | Q45: 0.96368413 | R45: 0.11330164 | T45: 0.15105023 | U45: 0.13429262
B46: 0.12291667 | C46: =HOUR(B46)*60+MINUTE(B46) -> 177 | D46: 3 | E46: {=C46-INDIRECT("C" & (ROW(D46) - D46))} -> 38 | G46: 2 | H46: 194182 | I46: =H46/506515 -> 0.38336871 | J46: =(I46*240-$C$325*2)/238 -> 0.38173955 | L46: =LN(J46) -> -0.9630167 | N46: {=L46-INDIRECT("L" & (ROW(L46)-D46))} -> -0.015771051 | O46: 267.26786 | P46: 7 | Q46: 159.21704 | R46: 6 | T46: 0.17792599 | U46: 1
...

Sheet final WP and GM
A1: sample ID | B1: al can+lid (g) | C1: can+lid+soil (g) | D1: soil(g) | E1: can+lid+soilpost 105℃(g) | F1: water lost (g) | G1: bulk density 105℃ (g/cm3) | H1: porosity 105℃ | I1: gravimetric water content (lost water/m105C soil) | J1: volumetric water content=gw*bulk density105℃ | K1: %saturation | L1: WP | M1: k (min-1) | N1: date of measurement | O1: note
A2: FGF-sf-20-1 | B2: 10.1708 | C2: 11.401 | D2: =C2-B2 -> 1.2302 | E2: 11.3156 | F2: =C2-E2 -> 0.0854 | G2: 1.0666894 | H2: ='characterization & setup'!$C$5 -> 51.645994 | I2: =F2/(D2-F2) -> 0.074598183 | J2: =I2*G2 -> 0.079573089 | K2: =100*I2*G2/(0.01*H2) -> 15.407408 | L2: -2.37 | N2: 45856
A3: FGF-sf-20-2 | B3: 10.5347 | C3: 11.567 | D3: =C3-B3 -> 1.0323 | E3: 11.4958 | F3: =C3-E3 -> 0.0712 | G3: 1.0666894 | H3: ='characterization & setup'!$C$5 -> 51.645994 | I3: =F3/(D3-F3) -> 0.074081781 | J3: =I3*G3 -> 0.079022249 | K3: =100*I3*G3/(0.01*H3) -> 15.300751 | L3: -2.2 | N3: 45856
A4: FGF-sf-20-3 | B4: 10.1564 | C4: 11.0789 | D4: =C4-B4 -> 0.9225 | E4: 11.0193 | F4: =C4-E4 -> 0.0596 | G4: 1.0666894 | H4: ='characterization & setup'!$C$5 -> 51.645994 | I4: =F4/(D4-F4) -> 0.069069417 | J4: =I4*G4 -> 0.073675613 | K4: =100*I4*G4/(0.01*H4) -> 14.265504 | L4: -2.35 | N4: 45856
A5: FGF-co-20-1 | B5: 10.0252 | C5: 10.9664 | D5: =C5-B5 -> 0.9412 | E5: 10.9009 | F5: =C5-E5 -> 0.0655 | G5: ='characterization & setup'!$C$50 -> 1.0945961 | H5: ='characterization & setup'!$C$52 -> 48.513825 | I5: =F5/(D5-F5) -> 0.074797305 | J5: =I5*G5 -> 0.081872836 | K5: =100*I5*G5/(0.01*H5) -> 16.876186 | L5: -2.25 | N5: 45856
A6: FGF-co-20-2 | B6: 10.6969 | C6: 11.7185 | D6: =C6-B6 -> 1.0216 | E6: 11.6462 | F6: =C6-E6 -> 0.0723 | G6: ='characterization & setup'!$C$50 -> 1.0945961 | H6: ='characterization & setup'!$C$52 -> 48.513825 | I6: =F6/(D6-F6) -> 0.076161382 | J6: =I6*G6 -> 0.08336595 | K6: =100*I6*G6/(0.01*H6) -> 17.183957 | L6: -2.33 | N6: 45856
A7: FGF-co-20-3 | B7: 9.7592 | C7: 10.4886 | D7: =C7-B7 -> 0.7294 | E7: 10.4391 | F7: =C7-E7 -> 0.0495 | G7: ='characterization & setup'!$C$50 -> 1.0945961 | H7: ='characterization & setup'!$C$52 -> 48.513825 | I7: =F7/(D7-F7) -> 0.072804824 | J7: =I7*G7 -> 0.079691875 | K7: =100*I7*G7/(0.01*H7) -> 16.426632 | L7: -2.49 | N7: 45856
A8: FGF-rm-20-1 | B8: 10.4381 | C8: 11.2354 | D8: =C8-B8 -> 0.7973 | E8: 11.1941 | F8: =C8-E8 -> 0.0413 | G8: ='characterization & setup'!$C$93 -> 1.0082588 | H8: ='characterization & setup'!$C$95 -> 53.952376 | I8: =F8/(D8-F8) -> 0.05462963 | J8: =I8*G8 -> 0.055080803 | K8: =100*I8*G8/(0.01*H8) -> 10.209152 | L8: -3.51 | N8: 45860
A9: FGF-rm-20-2 | B9: 10.1016 | C9: 10.6718 | D9: =C9-B9 -> 0.5702 | E9: 10.6383 | F9: =C9-E9 -> 0.0335 | G9: ='characterization & setup'!$C$93 -> 1.0082588 | H9: ='characterization & setup'!$C$95 -> 53.952376 | I9: =F9/(D9-F9) -> 0.062418483 | J9: =I9*G9 -> 0.062933983 | K9: =100*I9*G9/(0.01*H9) -> 11.664729 | L9: -3.33 | N9: 45860
A10: FGF-rm-20-3 | B10: 10.5869 | C10: 11.1984 | D10: =C10-B10 -> 0.6115 | E10: 11.1648 | F10: =C10-E10 -> 0.0336 | G10: ='characterization & setup'!$C$93 -> 1.0082588 | H10: ='characterization & setup'!$C$95 -> 53.952376 | I10: =F10/(D10-F10) -> 0.058141547 | J10: =I10*G10 -> 0.058621725 | K10: =100*I10*G10/(0.01*H10) -> 10.865457 | L10: -3.32 | N10: 45860
A11: FGF-or-20-1 | B11: 10.2897 | C11: 10.9095 | D11: =C11-B11 -> 0.6198 | E11: 10.8726 | F11: =C11-E11 -> 0.0369 | G11: ='characterization & setup'!$C$135 -> 1.1623209 | H11: ='characterization & setup'!$C$137 -> 47.525018 | I11: =F11/(D11-F11) -> 0.063304169 | J11: =I11*G11 -> 0.073579755 | K11: =100*I11*G11/(0.01*H11) -> 15.48232 | L11: -2.63 | N11: 45860
A12: FGF-or-20-2 | B12: 10.511 | C12: 11.3585 | D12: =C12-B12 -> 0.8475 | E12: 11.3121 | F12: =C12-E12 -> 0.0464 | G12: ='characterization & setup'!$C$135 -> 1.1623209 | H12: ='characterization & setup'!$C$137 -> 47.525018 | I12: =F12/(D12-F12) -> 0.05792036 | J12: =I12*G12 -> 0.067322042 | K12: =100*I12*G12/(0.01*H12) -> 14.1656 | L12: -3.24 | N12: 45860
A13: FGF-or-20-3 | B13: 10.7253 | C13: 11.6025 | D13: =C13-B13 -> 0.8772 | E13: 11.553 | F13: =C13-E13 -> 0.0495 | G13: ='characterization & setup'!$C$135 -> 1.1623209 | H13: ='characterization & setup'!$C$137 -> 47.525018 | I13: =F13/(D13-F13) -> 0.059804277 | J13: =I13*G13 -> 0.069511758 | K13: =100*I13*G13/(0.01*H13) -> 14.626351 | L13: -3.22 | N13: 45860
A14: FGF-sod-20-1 | B14: 9.886 | C14: 10.684 | D14: =C14-B14 -> 0.798 | E14: 10.6051 | F14: =C14-E14 -> 0.0789 | G14: ='characterization & setup'!$C$178 -> 0.76650691 | H14: ='characterization & setup'!$C$180 -> 61.626688 | I14: =F14/(D14-F14) -> 0.10972048 | J14: =I14*G14 -> 0.084101509 | K14: =100*I14*G14/(0.01*H14) -> 13.64693 | L14: -2.55 | N14: 45862
A15: FGF-sod-20-2 | B15: 10.2531 | C15: 10.9774 | D15: =C15-B15 -> 0.7243 | E15: 10.9107 | F15: =C15-E15 -> 0.0667 | G15: ='characterization & setup'!$C$178 -> 0.76650691 | H15: ='characterization & setup'!$C$180 -> 61.626688 | I15: =F15/(D15-F15) -> 0.10142944 | J15: =I15*G15 -> 0.077746367 | K15: =100*I15*G15/(0.01*H15) -> 12.615698 | L15: -3.42 | N15: 45862
A16: FGF-sod-20-3 | B16: 10.3783 | C16: 11.1231 | D16: =C16-B16 -> 0.7448 | E16: 11.0577 | F16: =C16-E16 -> 0.0654 | G16: ='characterization & setup'!$C$178 -> 0.76650691 | H16: ='characterization & setup'!$C$180 -> 61.626688 | I16: =F16/(D16-F16) -> 0.096261407 | J16: =I16*G16 -> 0.073785033 | K16: =100*I16*G16/(0.01*H16) -> 11.972903 | L16: -4 | N16: 45862
A17: FGF-bw-20-1 | B17: 10.482 | C17: 11.3434 | D17: =C17-B17 -> 0.8614 | E17: 11.2868 | F17: =C17-E17 -> 0.0566 | G17: ='characterization & setup'!$C$221 -> 1.1015441 | H17: ='characterization & setup'!$C$223 -> 51.215939 | I17: =F17/(D17-F17) -> 0.070328032 | J17: =I17*G17 -> 0.077469429 | K17: =100*I17*G17/(0.01*H17) -> 15.126039 | L17: -1.74 | N17: 45862
A18: FGF-bw-20-2 | B18: 10.0108 | C18: 10.5028 | D18: =C18-B18 -> 0.492 | E18: 10.4718 | F18: =C18-E18 -> 0.031 | G18: ='characterization & setup'!$C$221 -> 1.1015441 | H18: ='characterization & setup'!$C$223 -> 51.215939 | I18: =F18/(D18-F18) -> 0.067245119 | J18: =I18*G18 -> 0.074073465 | K18: =100*I18*G18/(0.01*H18) -> 14.462971 | L18: -1.83 | N18: 45862
A19: FGF-bw-20-3 | B19: 10.8547 | C19: 11.7077 | D19: =C19-B19 -> 0.853 | E19: 11.6485 | F19: =C19-E19 -> 0.0592 | G19: ='characterization & setup'!$C$221 -> 1.1015441 | H19: ='characterization & setup'!$C$223 -> 51.215939 | I19: =F19/(D19-F19) -> 0.074577979 | J19: =I19*G19 -> 0.082150933 | K19: =100*I19*G19/(0.01*H19) -> 16.040111 | L19: -1.57 | N19: 45862
A20: MF-as-20-1 | B20: 9.7683 | C20: 10.5981 | D20: =C20-B20 -> 0.8298 | E20: 10.5099 | F20: =C20-E20 -> 0.0882 | G20: ='characterization & setup'!$C$268 -> 1.3765272 | H20: ='characterization & setup'!$C$270 -> 42.524962 | I20: =F20/(D20-F20) -> 0.11893204 | J20: =I20*G20 -> 0.16371318 | K20: =100*I20*G20/(0.01*H20) -> 38.498137 | L20: -0.15 | N20: 45868
A21: MF-as-20-2 | B21: 10.7095 | C21: 11.29 | D21: =C21-B21 -> 0.5805 | E21: 11.2336 | F21: =C21-E21 -> 0.0564 | G21: ='characterization & setup'!$C$268 -> 1.3765272 | H21: ='characterization & setup'!$C$270 -> 42.524962 | I21: =F21/(D21-F21) -> 0.10761305 | J21: =I21*G21 -> 0.14813229 | K21: =100*I21*G21/(0.01*H21) -> 34.834196 | L21: -0.3 | N21: 45868
A22: MF-as-20-3 | B22: 9.8777 | C22: 10.4628 | D22: =C22-B22 -> 0.5851 | E22: 10.407 | F22: =C22-E22 -> 0.0558 | G22: ='characterization & setup'!$C$268 -> 1.3765272 | H22: ='characterization & setup'!$C$270 -> 42.524962 | I22: =F22/(D22-F22) -> 0.10542226 | J22: =I22*G22 -> 0.1451166 | K22: =100*I22*G22/(0.01*H22) -> 34.125039 | L22: -0.29 | N22: 45868
A23: MF-ch-20-1 | B23: 10.8019 | C23: 11.6034 | D23: =C23-B23 -> 0.8015 | E23: 11.524 | F23: =C23-E23 -> 0.0794 | G23: ='characterization & setup'!$C$315 -> 1.2980779 | H23: ='characterization & setup'!$C$317 -> 44.66846 | I23: =F23/(D23-F23) -> 0.10995707 | J23: =I23*G23 -> 0.14273285 | K23: =100*I23*G23/(0.01*H23) -> 31.953832 | L23: -0.44 | N23: 45868
A24: MF-ch-20-2 | B24: 10.5115 | C24: 11.3525 | D24: =C24-B24 -> 0.841 | E24: 11.2725 | F24: =C24-E24 -> 0.08 | G24: ='characterization & setup'!$C$315 -> 1.2980779 | H24: ='characterization & setup'!$C$317 -> 44.66846 | I24: =F24/(D24-F24) -> 0.10512484 | J24: =I24*G24 -> 0.13646023 | K24: =100*I24*G24/(0.01*H24) -> 30.549571 | L24: -0.79 | N24: 45868
A25: MF-ch-20-3 | B25: 10.342 | C25: 10.9881 | D25: =C25-B25 -> 0.6461 | E25: 10.9362 | F25: =C25-E25 -> 0.0519 | G25: ='characterization & setup'!$C$315 -> 1.2980779 | H25: ='characterization & setup'!$C$317 -> 44.66846 | I25: =F25/(D25-F25) -> 0.087344329 | J25: =I25*G25 -> 0.11337975 | K25: =100*I25*G25/(0.01*H25) -> 25.382506 | L25: -1.11 | N25: 45868

Sheet k vs %Sat or WP
A1: soil type | B1: temp | C1: target moisture | D1: replicate | E1: bulk density 105℃ (g/cm3) | F1: porosity 105℃ | G1: gravimetric water content (gH2O/g dry soil) | H1: volumetric water content (=gwc*bulk density) | I1: %saturation (=vwc/porosity) | J1: WP (Mpa) | K1: k (min-1) - All Data | L1: k (min-1) - No Tails | M1: incubation used air dried soil weight (g) | N1: weight normalized k (min-1 gSoil-1) - All Data | O1: weight normalized k (min-1 gSoil-1) - No Tails | P1: SOC (%) | Q1: SOC normalized k (min-1SOC-1) All Data | R1: SOC normalized k (min-1SOC-1) No Tails | S1: date of measurement | T1: performer of experiment | U1: meadow quadratic function calculated weight normalized k value | V1: ratio of weight normalized k between this soil/meadow soil | W1: avg ratio | X1: k max, assume at 24.815% at 22℃, using NJ meadow soil 22℃ QQ function | Y1: date of soil collection | Z1: note | AA1: No Tails
A2: sf | B2: 22 | C2: 20 | D2: 1 | E2: ='characterization & setup'!$C$3 -> 1.0666894 | F2: ='characterization & setup'!$C$5 -> 51.645994 | G2: ='final WP and GM'!I2 -> 0.074598183 | H2: =G2*E2 -> 0.079573089 | I2: =100*G2*E2/(0.01*F2) -> 15.407408 | J2: -2.37 | K2: ='H2 uptake rates'!$S$4 -> 0.0075743019 | L2: =ABS('H2 uptake rates'!$T$4) -> 0.0076919767 | M2: 2 | N2: =K2/M2 -> 0.0037871509 | O2: =L2/M2 -> 0.0038459883 | P2: ='characterization & setup'!$B$12 -> 3.4705243 | Q2: =N2/(0.01*P2) -> 0.10912331 | R2: =O2/(0.01*P2) -> 0.11081865 | S2: ='final WP and GM'!N2 -> 45856 | T2: QQ+CG | U2: =-0.000027*I2^2+ 0.00134*I2- 0.004008 -> 0.010228445 | V2: =N2/U2 -> 0.37025678 | X2: =W4*(-0.000027*24.815^2+0.00134*24.815-0.004008) -> 0.0044323735
A3: sf | B3: 22 | C3: 20 | D3: 2 | E3: ='characterization & setup'!$C$3 -> 1.0666894 | F3: ='characterization & setup'!$C$5 -> 51.645994 | G3: ='final WP and GM'!I3 -> 0.074081781 | H3: =G3*E3 -> 0.079022249 | I3: =100*G3*E3/(0.01*F3) -> 15.300751 | J3: -2.2 | K3: ='H2 uptake rates'!$S$17 -> 0.0060623948 | L3: =ABS('H2 uptake rates'!$T$17) -> 0.0053154392 | M3: 2 | N3: =K3/M3 -> 0.0030311974 | O3: =L3/M3 -> 0.0026577196 | P3: ='characterization & setup'!$B$12 -> 3.4705243 | Q3: =N3/(0.01*P3) -> 0.087341195 | R3: =O3/(0.01*P3) -> 0.076579771 | S3: ='final WP and GM'!N3 -> 45856 | T3: QQ+CG | U3: =-0.000027*I3^2+ 0.00134*I3- 0.004008 -> 0.010173956 | V3: =N3/U3 -> 0.29793696
A4: sf | B4: 22 | C4: 20 | D4: 3 | E4: ='characterization & setup'!$C$3 -> 1.0666894 | F4: ='characterization & setup'!$C$5 -> 51.645994 | G4: ='final WP and GM'!I4 -> 0.069069417 | H4: =G4*E4 -> 0.073675613 | I4: =100*G4*E4/(0.01*F4) -> 14.265504 | J4: -2.35 | K4: ='H2 uptake rates'!$S$30 -> 0.0074143161 | L4: =ABS('H2 uptake rates'!$T$30) -> 0.0056041337 | M4: 2 | N4: =K4/M4 -> 0.0037071581 | O4: =L4/M4 -> 0.0028020669 | P4: ='characterization & setup'!$B$12 -> 3.4705243 | Q4: =N4/(0.01*P4) -> 0.10681839 | R4: =O4/(0.01*P4) -> 0.080739006 | S4: ='final WP and GM'!N4 -> 45856 | T4: QQ+CG | U4: =-0.000027*I4^2+ 0.00134*I4- 0.004008 -> 0.009613151 | V4: =N4/U4 -> 0.38563402 | W4: =AVERAGE(V2:V4) -> 0.35127592
A5: corn | B5: 22 | C5: 20 | D5: 1 | E5: ='characterization & setup'!$C$50 -> 1.0945961 | F5: ='characterization & setup'!$C$52 -> 48.513825 | G5: ='final WP and GM'!I5 -> 0.074797305 | H5: =G5*E5 -> 0.081872836 | I5: =100*G5*E5/(0.01*F5) -> 16.876186 | J5: -2.25 | K5: ='H2 uptake rates'!$S$43 -> 0.0055938889 | L5: =ABS('H2 uptake rates'!$T$43) -> 0.0019994209 | M5: 2 | N5: =K5/M5 -> 0.0027969444 | O5: =L5/M5 -> 0.00099971047 | P5: ='characterization & setup'!$B$59 -> 3.4397477 | Q5: =N5/(0.01*P5) -> 0.081312489 | R5: =O5/(0.01*P5) -> 0.029063483 | S5: ='final WP and GM'!N5 -> 45856 | T5: QQ+CG | U5: =-0.000027*I5^2+ 0.00134*I5- 0.004008 -> 0.010916337 | V5: =N5/U5 -> 0.25621639 | X5: =W7*(-0.000027*24.815^2+0.00134*24.815-0.004008) -> 0.0037073875
A6: corn | B6: 22 | C6: 20 | D6: 2 | E6: ='characterization & setup'!$C$50 -> 1.0945961 | F6: ='characterization & setup'!$C$52 -> 48.513825 | G6: ='final WP and GM'!I6 -> 0.076161382 | H6: =G6*E6 -> 0.08336595 | I6: =100*G6*E6/(0.01*F6) -> 17.183957 | J6: -2.33 | K6: ='H2 uptake rates'!$S$56 -> 0.0074750451 | L6: =ABS('H2 uptake rates'!$T$56) -> 0.0082525768 | M6: 2 | N6: =K6/M6 -> 0.0037375226 | O6: =L6/M6 -> 0.0041262884 | P6: ='characterization & setup'!$B$59 -> 3.4397477 | Q6: =N6/(0.01*P6) -> 0.10865688 | R6: =O6/(0.01*P6) -> 0.11995904 | S6: ='final WP and GM'!N6 -> 45856 | T6: QQ+CG | U6: =-0.000027*I6^2+ 0.00134*I6- 0.004008 -> 0.011045716 | V6: =N6/U6 -> 0.33836851
A7: corn | B7: 22 | C7: 20 | D7: 3 | E7: ='characterization & setup'!$C$50 -> 1.0945961 | F7: ='characterization & setup'!$C$52 -> 48.513825 | G7: ='final WP and GM'!I7 -> 0.072804824 | H7: =G7*E7 -> 0.079691875 | I7: =100*G7*E7/(0.01*F7) -> 16.426632 | J7: -2.49 | K7: ='H2 uptake rates'!$S$69 -> 0.0061494893 | L7: =ABS('H2 uptake rates'!$T$69) -> 0.0054518426 | M7: 2 | N7: =K7/M7 -> 0.0030747447 | O7: =L7/M7 -> 0.0027259213 | P7: ='characterization & setup'!$B$59 -> 3.4397477 | Q7: =N7/(0.01*P7) -> 0.089388669 | R7: =O7/(0.01*P7) -> 0.07924771 | S7: ='final WP and GM'!N7 -> 45856 | T7: QQ+CG | U7: =-0.000027*I7^2+ 0.00134*I7- 0.004008 -> 0.010718162 | V7: =N7/U7 -> 0.28687237 | W7: =AVERAGE(V5:V7) -> 0.29381909
A8: rm | B8: 22 | C8: 20 | D8: 1 | E8: ='characterization & setup'!$C$93 -> 1.0082588 | F8: ='characterization & setup'!$C$95 -> 53.952376 | G8: ='final WP and GM'!I8 -> 0.05462963 | H8: =G8*E8 -> 0.055080803 | I8: =100*G8*E8/(0.01*F8) -> 10.209152 | J8: -3.51 | K8: ='H2 uptake rates'!$S$83 -> 0.0071885002 | L8: =ABS('H2 uptake rates'!$T$83) -> 0.0081656851 | M8: 2 | N8: =K8/M8 -> 0.0035942501 | O8: =L8/M8 -> 0.0040828426 | P8: ='characterization & setup'!$B$102 -> 4.4487296 | Q8: =N8/(0.01*P8) -> 0.080792731 | R8: =O8/(0.01*P8) -> 0.091775472 | S8: ='final WP and GM'!N8 -> 45860 | T8: QQ+CG | U8: =-0.000027*I8^2+ 0.00134*I8- 0.004008 -> 0.0068581409 | V8: =N8/U8 -> 0.5240852 | X8: =W10*(-0.000027*24.815^2+0.00134*24.815-0.004008) -> 0.0063976938
A9: rm | B9: 22 | C9: 20 | D9: 2 | E9: ='characterization & setup'!$C$93 -> 1.0082588 | F9: ='characterization & setup'!$C$95 -> 53.952376 | G9: ='final WP and GM'!I9 -> 0.062418483 | H9: =G9*E9 -> 0.062933983 | I9: =100*G9*E9/(0.01*F9) -> 11.664729 | J9: -3.33 | K9: ='H2 uptake rates'!$S$96 -> 0.0073688396 | L9: =ABS('H2 uptake rates'!$T$96) -> 0.0078716761 | M9: 2 | N9: =K9/M9 -> 0.0036844198 | O9: =L9/M9 -> 0.003935838 | P9: ='characterization & setup'!$B$102 -> 4.4487296 | Q9: =N9/(0.01*P9) -> 0.082819595 | R9: =O9/(0.01*P9) -> 0.088471056 | S9: ='final WP and GM'!N9 -> 45860 | T9: QQ+CG | U9: =-0.000027*I9^2+ 0.00134*I9- 0.004008 -> 0.0079489573 | V9: =N9/U9 -> 0.46350983
A10: rm | B10: 22 | C10: 20 | D10: 3 | E10: ='characterization & setup'!$C$93 -> 1.0082588 | F10: ='characterization & setup'!$C$95 -> 53.952376 | G10: ='final WP and GM'!I10 -> 0.058141547 | H10: =G10*E10 -> 0.058621725 | I10: =100*G10*E10/(0.01*F10) -> 10.865457 | J10: -3.32 | K10: ='H2 uptake rates'!$S$109 -> 0.00785756 | L10: =ABS('H2 uptake rates'!$T$109) -> 0.0083296856 | M10: 2 | N10: =K10/M10 -> 0.00392878 | O10: =L10/M10 -> 0.0041648428 | P10: ='characterization & setup'!$B$102 -> 4.4487296 | Q10: =N10/(0.01*P10) -> 0.088312403 | R10: =O10/(0.01*P10) -> 0.0936187 | S10: ='final WP and GM'!N10 -> 45860 | T10: QQ+CG | U10: =-0.000027*I10^2+ 0.00134*I10- 0.004008 -> 0.0073641425 | V10: =N10/U10 -> 0.53350135 | W10: =AVERAGE(V8:V10) -> 0.50703213
A11: oregano | B11: 22 | C11: 20 | D11: 1 | E11: ='characterization & setup'!$C$135 -> 1.1623209 | F11: ='characterization & setup'!$C$137 -> 47.525018 | G11: ='final WP and GM'!I11 -> 0.063304169 | H11: =G11*E11 -> 0.073579755 | I11: =100*G11*E11/(0.01*F11) -> 15.48232 | J11: -2.63 | K11: ='H2 uptake rates'!$S$122 -> 0.0041951814 | L11: =ABS('H2 uptake rates'!$T$122) -> 0.0050064837 | M11: 2 | N11: =K11/M11 -> 0.0020975907 | O11: =L11/M11 -> 0.0025032418 | P11: ='characterization & setup'!$B$144 -> 3.7927181 | Q11: =N11/(0.01*P11) -> 0.055305736 | R11: =O11/(0.01*P11) -> 0.066001262 | S11: ='final WP and GM'!N11 -> 45860 | T11: QQ+CG | U11: =-0.000027*I11^2+ 0.00134*I11- 0.004008 -> 0.010266349 | V11: =N11/U11 -> 0.20431711 | X11: =W13*(-0.000027*24.815^2+0.00134*24.815-0.004008) -> 0.0029784665
A12: oregano | B12: 22 | C12: 20 | D12: 2 | E12: ='characterization & setup'!$C$135 -> 1.1623209 | F12: ='characterization & setup'!$C$137 -> 47.525018 | G12: ='final WP and GM'!I12 -> 0.05792036 | H12: =G12*E12 -> 0.067322042 | I12: =100*G12*E12/(0.01*F12) -> 14.1656 | J12: -3.24 | K12: ='H2 uptake rates'!$S$135 -> 0.0048906119 | L12: =ABS('H2 uptake rates'!$T$135) -> 0.0052807707 | M12: 2 | N12: =K12/M12 -> 0.0024453059 | O12: =L12/M12 -> 0.0026403854 | P12: ='characterization & setup'!$B$144 -> 3.7927181 | Q12: =N12/(0.01*P12) -> 0.064473706 | R12: =O12/(0.01*P12) -> 0.069617231 | S12: ='final WP and GM'!N12 -> 45860 | T12: QQ+CG | U12: =-0.000027*I12^2+ 0.00134*I12- 0.004008 -> 0.0095559702 | V12: =N12/U12 -> 0.255893
A13: oregano | B13: 22 | C13: 20 | D13: 3 | E13: ='characterization & setup'!$C$135 -> 1.1623209 | F13: ='characterization & setup'!$C$137 -> 47.525018 | G13: ='final WP and GM'!I13 -> 0.059804277 | H13: =G13*E13 -> 0.069511758 | I13: =100*G13*E13/(0.01*F13) -> 14.626351 | J13: -3.22 | K13: ='H2 uptake rates'!$S$148 -> 0.0048671811 | L13: =ABS('H2 uptake rates'!$T$148) -> 0.0041387414 | M13: 2 | N13: =K13/M13 -> 0.0024335906 | O13: =L13/M13 -> 0.0020693707 | P13: ='characterization & setup'!$B$144 -> 3.7927181 | Q13: =N13/(0.01*P13) -> 0.064164815 | R13: =O13/(0.01*P13) -> 0.054561679 | S13: ='final WP and GM'!N13 -> 45860 | T13: QQ+CG | U13: =-0.000027*I13^2+ 0.00134*I13- 0.004008 -> 0.0098151963 | V13: =N13/U13 -> 0.2479411 | W13: =AVERAGE(V11:V13) -> 0.2360504
A14: sod | B14: 22 | C14: 20 | D14: 1 | E14: ='characterization & setup'!$C$178 -> 0.76650691 | F14: ='characterization & setup'!$C$180 -> 61.626688 | G14: ='final WP and GM'!I14 -> 0.10972048 | H14: =G14*E14 -> 0.084101509 | I14: =100*G14*E14/(0.01*F14) -> 13.64693 | J14: -2.55 | K14: ='H2 uptake rates'!$S$162 -> 0.016072171 | L14: =ABS('H2 uptake rates'!$T$162) -> 0.01443157 | M14: 2 | N14: =K14/M14 -> 0.0080360853 | O14: =L14/M14 -> 0.0072157851 | P14: ='characterization & setup'!$B$187 -> 7.2814771 | Q14: =N14/(0.01*P14) -> 0.11036339 | R14: =O14/(0.01*P14) -> 0.09909782 | S14: ='final WP and GM'!N17 -> 45862 | T14: QQ+CG | U14: =-0.000027*I14^2+ 0.00134*I14- 0.004008 -> 0.0092504412 | V14: =N14/U14 -> 0.86872454 | X14: =W16*(-0.000027*24.815^2+0.00134*24.815-0.004008) -> 0.012886966
A15: sod | B15: 22 | C15: 20 | D15: 2 | E15: ='characterization & setup'!$C$178 -> 0.76650691 | F15: ='characterization & setup'!$C$180 -> 61.626688 | G15: ='final WP and GM'!I15 -> 0.10142944 | H15: =G15*E15 -> 0.077746367 | I15: =100*G15*E15/(0.01*F15) -> 12.615698 | J15: -3.42 | K15: ='H2 uptake rates'!$S$175 -> 0.019019069 | L15: =ABS('H2 uptake rates'!$T$175) -> 0.012933984 | M15: 2 | N15: =K15/M15 -> 0.0095095344 | O15: =L15/M15 -> 0.0064669918 | P15: ='characterization & setup'!$B$187 -> 7.2814771 | Q15: =N15/(0.01*P15) -> 0.13059897 | R15: =O15/(0.01*P15) -> 0.088814284 | S15: ='final WP and GM'!N18 -> 45862 | T15: QQ+CG | U15: =-0.000027*I15^2+ 0.00134*I15- 0.004008 -> 0.0085998276 | V15: =N15/U15 -> 1.105782
A16: sod | B16: 22 | C16: 20 | D16: 3 | E16: ='characterization & setup'!$C$178 -> 0.76650691 | F16: ='characterization & setup'!$C$180 -> 61.626688 | G16: ='final WP and GM'!I16 -> 0.096261407 | H16: =G16*E16 -> 0.073785033 | I16: =100*G16*E16/(0.01*F16) -> 11.972903 | J16: -4 | K16: ='H2 uptake rates'!$S$188 -> 0.017791374 | L16: =ABS('H2 uptake rates'!$T$188) -> 0.017550432 | M16: 2 | N16: =K16/M16 -> 0.0088956868 | O16: =L16/M16 -> 0.0087752159 | P16: ='characterization & setup'!$B$187 -> 7.2814771 | Q16: =N16/(0.01*P16) -> 0.12216871 | R16: =O16/(0.01*P16) -> 0.12051423 | S16: ='final WP and GM'!N19 -> 45862 | T16: QQ+CG | U16: =-0.000027*I16^2+ 0.00134*I16- 0.004008 -> 0.0081652288 | V16: =N16/U16 -> 1.0894596 | W16: =AVERAGE(V14:V16) -> 1.021322
A17: bw | B17: 22 | C17: 20 | D17: 1 | E17: ='characterization & setup'!$C$221 -> 1.1015441 | F17: ='characterization & setup'!$C$223 -> 51.215939 | G17: ='final WP and GM'!I17 -> 0.070328032 | H17: =G17*E17 -> 0.077469429 | I17: =100*G17*E17/(0.01*F17) -> 15.126039 | J17: -1.74 | K17: ='H2 uptake rates'!$S$201 -> 0.0040894438 | L17: =ABS('H2 uptake rates'!$T$201) -> 0.00047363045 | M17: 2 | N17: =K17/M17 -> 0.0020447219 | O17: =L17/M17 -> 0.00023681522 | P17: ='characterization & setup'!$B$230 -> 3.5938467 | Q17: =N17/(0.01*P17) -> 0.056895078 | R17: =O17/(0.01*P17) -> 0.0065894637 | S17: ='final WP and GM'!N14 -> 45862 | T17: QQ+CG | U17: =-0.000027*I17^2+ 0.00134*I17- 0.004008 -> 0.010083372 | V17: =N17/U17 -> 0.20278156 | X17: =W19*(-0.000027*24.815^2+0.00134*24.815-0.004008) -> 0.0023139424
A18: bw | B18: 22 | C18: 20 | D18: 2 | E18: ='characterization & setup'!$C$221 -> 1.1015441 | F18: ='characterization & setup'!$C$223 -> 51.215939 | G18: ='final WP and GM'!I18 -> 0.067245119 | H18: =G18*E18 -> 0.074073465 | I18: =100*G18*E18/(0.01*F18) -> 14.462971 | J18: -1.83 | K18: ='H2 uptake rates'!$S$214 -> 0.0031804469 | L18: =ABS('H2 uptake rates'!$T$214) -> 0.0031858786 | M18: 2 | N18: =K18/M18 -> 0.0015902235 | O18: =L18/M18 -> 0.0015929393 | P18: ='characterization & setup'!$B$230 -> 3.5938467 | Q18: =N18/(0.01*P18) -> 0.044248505 | R18: =O18/(0.01*P18) -> 0.044324074 | S18: ='final WP and GM'!N15 -> 45862 | T18: QQ+CG | U18: =-0.000027*I18^2+ 0.00134*I18- 0.004008 -> 0.0097245879 | V18: =N18/U18 -> 0.16352605
A19: bw | B19: 22 | C19: 20 | D19: 3 | E19: ='characterization & setup'!$C$221 -> 1.1015441 | F19: ='characterization & setup'!$C$223 -> 51.215939 | G19: ='final WP and GM'!I19 -> 0.074577979 | H19: =G19*E19 -> 0.082150933 | I19: =100*G19*E19/(0.01*F19) -> 16.040111 | J19: -1.57 | K19: ='H2 uptake rates'!$S$227 -> 0.0038751737 | L19: =ABS('H2 uptake rates'!$T$227) -> 0.0031443802 | M19: 2 | N19: =K19/M19 -> 0.0019375868 | O19: =L19/M19 -> 0.0015721901 | P19: ='characterization & setup'!$B$230 -> 3.5938467 | Q19: =N19/(0.01*P19) -> 0.053914009 | R19: =O19/(0.01*P19) -> 0.043746721 | S19: ='final WP and GM'!N16 -> 45862 | T19: QQ+CG | U19: =-0.000027*I19^2+ 0.00134*I19- 0.004008 -> 0.010539049 | V19: =N19/U19 -> 0.18384835 | W19: =AVERAGE(V17:V19) -> 0.18338532
A20: as | B20: 22 | C20: 20 | D20: 1 | E20: ='characterization & setup'!$C$268 -> 1.3765272 | F20: ='characterization & setup'!$C$270 -> 42.524962 | G20: ='final WP and GM'!I20 -> 0.11893204 | H20: =G20*E20 -> 0.16371318 | I20: =100*G20*E20/(0.01*F20) -> 38.498137 | J20: -0.15 | K20: ='H2 uptake rates'!$S$241 -> 0.0075852368 | L20: =ABS('H2 uptake rates'!$T$241) -> 0.0055696199 | M20: 2 | N20: =K20/M20 -> 0.0037926184 | O20: =L20/M20 -> 0.00278481 | P20: ='characterization & setup'!$B$277 -> 1.8613495 | Q20: =N20/(0.01*P20) -> 0.20375638 | R20: =O20/(0.01*P20) -> 0.14961242 | S20: ='final WP and GM'!N20 -> 45868 | T20: QQ+CG | U20: =-0.000027*I20^2+ 0.00134*I20- 0.004008 -> 0.0075626268 | V20: =N20/U20 -> 0.50149485
A21: as | B21: 22 | C21: 20 | D21: 2 | E21: ='characterization & setup'!$C$268 -> 1.3765272 | F21: ='characterization & setup'!$C$270 -> 42.524962 | G21: ='final WP and GM'!I21 -> 0.10761305 | H21: =G21*E21 -> 0.14813229 | I21: =100*G21*E21/(0.01*F21) -> 34.834196 | J21: -0.3 | K21: ='H2 uptake rates'!$S$254 -> 0.0084868582 | L21: =ABS('H2 uptake rates'!$T$254) -> 0.0067293746 | M21: 2 | N21: =K21/M21 -> 0.0042434291 | O21: =L21/M21 -> 0.0033646873 | P21: ='characterization & setup'!$B$277 -> 1.8613495 | Q21: =N21/(0.01*P21) -> 0.22797594 | R21: =O21/(0.01*P21) -> 0.18076601 | S21: ='final WP and GM'!N21 -> 45868 | T21: QQ+CG | U21: =-0.000027*I21^2+ 0.00134*I21- 0.004008 -> 0.0099074499 | V21: =N21/U21 -> 0.4283069 | X21: =AVERAGE(I20:I22) -> 35.819124 | Y21: kmax corresponding average %Sat
A22: as | B22: 22 | C22: 20 | D22: 3 | E22: ='characterization & setup'!$C$268 -> 1.3765272 | F22: ='characterization & setup'!$C$270 -> 42.524962 | G22: ='final WP and GM'!I22 -> 0.10542226 | H22: =G22*E22 -> 0.1451166 | I22: =100*G22*E22/(0.01*F22) -> 34.125039 | J22: -0.29 | K22: ='H2 uptake rates'!$S$267 -> 0.0080525731 | L22: =ABS('H2 uptake rates'!$T$267) -> 0.008648658 | M22: 2 | N22: =K22/M22 -> 0.0040262865 | O22: =L22/M22 -> 0.004324329 | P22: ='characterization & setup'!$B$277 -> 1.8613495 | Q22: =N22/(0.01*P22) -> 0.21631008 | R22: =O22/(0.01*P22) -> 0.23232225 | S22: ='final WP and GM'!N22 -> 45868 | T22: QQ+CG | U22: =-0.000027*I22^2+ 0.00134*I22- 0.004008 -> 0.010277559 | V22: =N22/U22 -> 0.39175515 | X22: =AVERAGE(N20:N22) -> 0.004020778 | Y22: kmax calculated by averaging the three measurements
A23: ch | B23: 22 | C23: 20 | D23: 1 | E23: ='characterization & setup'!$C$315 -> 1.2980779 | F23: ='characterization & setup'!$C$317 -> 44.66846 | G23: ='final WP and GM'!I23 -> 0.10995707 | H23: =G23*E23 -> 0.14273285 | I23: =100*G23*E23/(0.01*F23) -> 31.953832 | J23: -0.44 | K23: ='H2 uptake rates'!$S$280 -> 0.0025973515 | L23: =ABS('H2 uptake rates'!$T$280) -> 0.0014044847 | M23: 2 | N23: =K23/M23 -> 0.0012986758 | O23: =L23/M23 -> 0.00070224233 | P23: ='characterization & setup'!$B$324 -> 2.1535725 | Q23: =N23/(0.01*P23) -> 0.060303322 | R23: =O23/(0.01*P23) -> 0.032608251 | S23: ='final WP and GM'!N23 -> 45868 | T23: QQ+CG | U23: =-0.000027*I23^2+ 0.00134*I23- 0.004008 -> 0.011241856 | V23: =N23/U23 -> 0.11552148
A24: ch | B24: 22 | C24: 20 | D24: 2 | E24: ='characterization & setup'!$C$315 -> 1.2980779 | F24: ='characterization & setup'!$C$317 -> 44.66846 | G24: ='final WP and GM'!I24 -> 0.10512484 | H24: =G24*E24 -> 0.13646023 | I24: =100*G24*E24/(0.01*F24) -> 30.549571 | J24: -0.79 | K24: ='H2 uptake rates'!$S$293 -> 0.0018700691 | L24: =ABS('H2 uptake rates'!$T$293) -> 0.0033351343 | M24: 2 | N24: =K24/M24 -> 0.00093503456 | O24: =L24/M24 -> 0.0016675672 | P24: ='characterization & setup'!$B$324 -> 2.1535725 | Q24: =N24/(0.01*P24) -> 0.043417835 | R24: =O24/(0.01*P24) -> 0.077432598 | S24: ='final WP and GM'!N24 -> 45868 | T24: QQ+CG | U24: =-0.000027*I24^2+ 0.00134*I24- 0.004008 -> 0.011729965 | V24: =N24/U24 -> 0.079713327 | X24: =AVERAGE(I23:I25) -> 29.295303 | Y24: kmax corresponding average %Sat
A25: ch | B25: 22 | C25: 20 | D25: 3 | E25: ='characterization & setup'!$C$315 -> 1.2980779 | F25: ='characterization & setup'!$C$317 -> 44.66846 | G25: ='final WP and GM'!I25 -> 0.087344329 | H25: =G25*E25 -> 0.11337975 | I25: =100*G25*E25/(0.01*F25) -> 25.382506 | J25: -1.11 | K25: ='H2 uptake rates'!$S$306 -> 0.0014745879 | L25: =ABS('H2 uptake rates'!$T$306) -> 0.00024331048 | M25: 2 | N25: =K25/M25 -> 0.00073729397 | O25: =L25/M25 -> 0.00012165524 | P25: ='characterization & setup'!$B$324 -> 2.1535725 | Q25: =N25/(0.01*P25) -> 0.034235855 | R25: =O25/(0.01*P25) -> 0.0056489966 | S25: ='final WP and GM'!N25 -> 45868 | T25: QQ+CG | U25: =-0.000027*I25^2+ 0.00134*I25- 0.004008 -> 0.012609225 | V25: =N25/U25 -> 0.058472586 | X25: =AVERAGE(N23:N25) -> 0.00099033477 | Y25: kmax calculated by averaging the three measurements
