Workbook

Sheet Characterization
A1: Soil Sample Name | B1: Mass Grad Cyl g | C1: Volume Soil mL | D1: Mass Grad Cyl + Soil | E1: Mass Soil | F1: Volume Water | G1: Volume Soil + Water | H1: Volume Soil Particles | I1: Bulk Density Air Dry g/ml | J1: Particle Mass Density Air Dry g/ml | K1: Porosity Air Dry % | L1: Avg. Mass g Water/Mass g Air Dry Soil | M1: Bulk Density 105 g/ml | N1: PMD 105 g/ml | O1: Porosity 105 % | P1: GM 105 | Q1: Base Sat. % | R1: Avg. % OM | S1: Avg % SOC | T1: g Water to add for 15% | U1: g Water to add for 25%
A2: Soybean Undisturbed | B2: 42.33 | C2: 50 | D2: 92.61 | E2: =D2-B2 -> 50.28 | F2: 50 | G2: 74 | H2: =G2-F2 -> 24 | I2: =E2/C2 -> 1.0056 | J2: =E2/H2 -> 2.095 | K2: =100-(100*I2/J2) -> 52 | L2: =AVERAGE('Oven Drying & Combustion'!H2:H4) -> 0.02045474 | M2: =I2*(1-$L2) -> 0.98503071 | N2: =J2*(1-$L2) -> 2.0521473 | O2: =K2*(1-$L2) -> 50.936354 | P2: =AVERAGE('Oven Drying & Combustion'!I2:I4) -> 0.020882129 | Q2: =P2*M2/(0.01*O2) -> 0.040382824 | R2: =AVERAGE('Oven Drying & Combustion'!L2:L4) -> 0.08287958 | S2: =R2*0.58 -> 0.048070157 | T2: =(15*$O2*(2*(1-$L2))*(10^-4)/$M2)-(2*$L2) -> 0.11104862 | U2: =25*$O2*(2*(1-$L2))*(10^-4)/$M2-(2*$L2) -> 0.21235401 | V2: =Q2/P2 -> 1.9338462
A3: Soybean Center | B3: 121.07 | C3: 50 | D3: 177.42 | E3: =D3-B3 -> 56.35 | F3: 50 | G3: 76 | H3: =G3-F3 -> 26 | I3: =E3/C3 -> 1.127 | J3: =E3/H3 -> 2.1673077 | K3: =100-(100*I3/J3) -> 48 | L3: =AVERAGE('Oven Drying & Combustion'!H5:H7) -> 0.020842426 | M3: =I3*(1-$L3) -> 1.1035106 | N3: =J3*(1-$L3) -> 2.1221357 | O3: =K3*(1-$L3) -> 46.999564 | P3: =AVERAGE('Oven Drying & Combustion'!I5:I7) -> 0.021286444 | Q3: =P3*M3/(0.01*O3) -> 0.049978798 | R3: =AVERAGE('Oven Drying & Combustion'!L5:L7) -> 0.0589435 | S3: =R3*0.58 -> 0.03418723 | T3: =(15*$O3*(2*(1-$L3))*(10^-4)/$M3)-(2*$L3) -> 0.0834249 | U3: =25*$O3*(2*(1-$L3))*(10^-4)/$M3-(2*$L3) -> 0.1668314 | V3: =Q3/P3 -> 2.3479167
A4: FGF Rosemary | B4: 120.41 | C4: 50 | D4: 180.68 | E4: =D4-B4 -> 60.27 | F4: 50 | G4: 79 | H4: =G4-F4 -> 29 | I4: =E4/C4 -> 1.2054 | J4: =E4/H4 -> 2.0782759 | K4: =100-(100*I4/J4) -> 42 | L4: =AVERAGE('Oven Drying & Combustion'!H8:H10) -> 0.026174237 | M4: =I4*(1-$L4) -> 1.1738496 | N4: =J4*(1-$L4) -> 2.0238786 | O4: =K4*(1-$L4) -> 40.900682 | P4: =AVERAGE('Oven Drying & Combustion'!I8:I10) -> 0.026877914 | Q4: =P4*M4/(0.01*O4) -> 0.077139613 | R4: =AVERAGE('Oven Drying & Combustion'!L8:L10) -> 0.077033604 | S4: =R4*0.58 -> 0.04467949 | T4: =(15*$O4*(2*(1-$L4))*(10^-4)/$M4)-(2*$L4) -> 0.04944516 | U4: =25*$O4*(2*(1-$L4))*(10^-4)/$M4-(2*$L4) -> 0.11730758 | V4: =Q4/P4 -> 2.87
A5: FGF Oregano | B5: 121.46 | C5: 50 | D5: 184.44 | E5: =D5-B5 -> 62.98 | F5: 50 | G5: 79 | H5: =G5-F5 -> 29 | I5: =E5/C5 -> 1.2596 | J5: =E5/H5 -> 2.1717241 | K5: =100-(100*I5/J5) -> 42 | L5: =AVERAGE('Oven Drying & Combustion'!H11:H13) -> 0.02122671 | M5: =I5*(1-$L5) -> 1.2328628 | N5: =J5*(1-$L5) -> 2.1256256 | O5: =K5*(1-$L5) -> 41.108478 | P5: =AVERAGE('Oven Drying & Combustion'!I11:I13) -> 0.021687842 | Q5: =P5*M5/(0.01*O5) -> 0.065042872 | R5: =AVERAGE('Oven Drying & Combustion'!L11:L13) -> 0.06870209 | S5: =R5*0.58 -> 0.039847212 | T5: =(15*$O5*(2*(1-$L5))*(10^-4)/$M5)-(2*$L5) -> 0.055454992 | U5: =25*$O5*(2*(1-$L5))*(10^-4)/$M5-(2*$L5) -> 0.12072727 | V5: =Q5/P5 -> 2.9990476
A6: FGF Buckwheat | B6: 121.47 | C6: 50 | D6: 176.61 | E6: =D6-B6 -> 55.14 | F6: 50 | G6: 76 | H6: =G6-F6 -> 26 | I6: =E6/C6 -> 1.1028 | J6: =E6/H6 -> 2.1207692 | K6: =100-(100*I6/J6) -> 48 | L6: =AVERAGE('Oven Drying & Combustion'!H14:H16) -> 0.02281322 | M6: =I6*(1-$L6) -> 1.0776416 | N6: =J6*(1-$L6) -> 2.0723877 | O6: =K6*(1-$L6) -> 46.904965 | P6: =AVERAGE('Oven Drying & Combustion'!I14:I16) -> 0.023346483 | Q6: =P6*M6/(0.01*O6) -> 0.053638544 | R6: =AVERAGE('Oven Drying & Combustion'!L14:L16) -> 0.06778143 | S6: =R6*0.58 -> 0.039313229 | T6: =(15*$O6*(2*(1-$L6))*(10^-4)/$M6)-(2*$L6) -> 0.081971398 | U6: =25*$O6*(2*(1-$L6))*(10^-4)/$M6-(2*$L6) -> 0.16703662 | V6: =Q6/P6 -> 2.2975
A7: FGF Sod | B7: 121.01 | C7: 50 | D7: 172.31 | E7: =D7-B7 -> 51.3 | F7: 50 | G7: 76 | H7: =G7-F7 -> 26 | I7: =E7/C7 -> 1.026 | J7: =E7/H7 -> 1.9730769 | K7: =100-(100*I7/J7) -> 48 | L7: =AVERAGE('Oven Drying & Combustion'!H17:H19) -> 0.02813944 | M7: =I7*(1-$L7) -> 0.99712893 | N7: =J7*(1-$L7) -> 1.9175556 | O7: =K7*(1-$L7) -> 46.649307 | P7: =AVERAGE('Oven Drying & Combustion'!I17:I19) -> 0.028954669 | Q7: =P7*M7/(0.01*O7) -> 0.061890605 | R7: =AVERAGE('Oven Drying & Combustion'!L17:L19) -> 0.11499576 | S7: =R7*0.58 -> 0.066697539 | T7: =(15*$O7*(2*(1-$L7))*(10^-4)/$M7)-(2*$L7) -> 0.080122603 | U7: =25*$O7*(2*(1-$L7))*(10^-4)/$M7-(2*$L7) -> 0.17105692 | V7: =Q7/P7 -> 2.1375
A8: FGF Sunflower | B8: 126.95 | C8: 50 | D8: 190.3 | E8: =D8-B8 -> 63.35 | F8: 50 | G8: 78 | H8: =G8-F8 -> 28 | I8: =E8/C8 -> 1.267 | J8: =E8/H8 -> 2.2625 | K8: =100-(100*I8/J8) -> 44 | L8: =AVERAGE('Oven Drying & Combustion'!H20:H22) -> 0.022388381 | M8: =I8*(1-$L8) -> 1.2386339 | N8: =J8*(1-$L8) -> 2.2118463 | O8: =K8*(1-$L8) -> 43.014911 | P8: =AVERAGE('Oven Drying & Combustion'!I20:I22) -> 0.022901165 | Q8: =P8*M8/(0.01*O8) -> 0.065944946 | R8: =AVERAGE('Oven Drying & Combustion'!L20:L22) -> 0.07026541 | S8: =R8*0.58 -> 0.040753938 | T8: =(15*$O8*(2*(1-$L8))*(10^-4)/$M8)-(2*$L8) -> 0.057073856 | U8: =25*$O8*(2*(1-$L8))*(10^-4)/$M8-(2*$L8) -> 0.12497427 | V8: =Q8/P8 -> 2.8795455
A9: FGF Corn | B9: 42.34 | C9: 50 | D9: 105.13 | E9: =D9-B9 -> 62.79 | F9: 50 | G9: 78 | H9: =G9-F9 -> 28 | I9: =E9/C9 -> 1.2558 | J9: =E9/H9 -> 2.2425 | K9: =100-(100*I9/J9) -> 44 | L9: =AVERAGE('Oven Drying & Combustion'!H23:H25) -> 0.022857187 | M9: =I9*(1-$L9) -> 1.2270959 | N9: =J9*(1-$L9) -> 2.1912428 | O9: =K9*(1-$L9) -> 42.994284 | P9: =AVERAGE('Oven Drying & Combustion'!I23:I25) -> 0.023393009 | Q9: =P9*M9/(0.01*O9) -> 0.066765775 | R9: =AVERAGE('Oven Drying & Combustion'!L23:L25) -> 0.068808094 | S9: =R9*0.58 -> 0.039908695 | T9: =(15*$O9*(2*(1-$L9))*(10^-4)/$M9)-(2*$L9) -> 0.056995333 | U9: =25*$O9*(2*(1-$L9))*(10^-4)/$M9-(2*$L9) -> 0.12546847 | V9: =Q9/P9 -> 2.8540909
C10: 50 | E10: =D10-B10 -> 0 | F10: 50 | H10: =G10-F10 -> -50 | I10: =E10/C10 -> 0 | J10: =E10/H10 -> 0 | K10: =100-(100*I10/J10) -> #DIV/0!
C11: 50 | E11: =D11-B11 -> 0 | F11: 50 | H11: =G11-F11 -> -50 | I11: =E11/C11 -> 0 | J11: =E11/H11 -> 0 | K11: =100-(100*I11/J11) -> #DIV/0!
C12: 50 | E12: =D12-B12 -> 0 | F12: 50 | H12: =G12-F12 -> -50 | I12: =E12/C12 -> 0 | J12: =E12/H12 -> 0 | K12: =100-(100*I12/J12) -> #DIV/0!
C13: 50 | E13: =D13-B13 -> 0 | F13: 50 | H13: =G13-F13 -> -50 | I13: =E13/C13 -> 0 | J13: =E13/H13 -> 0 | K13: =100-(100*I13/J13) -> #DIV/0!
C14: 50 | E14: =D14-B14 -> 0 | F14: 50 | H14: =G14-F14 -> -50 | I14: =E14/C14 -> 0 | J14: =E14/H14 -> 0 | K14: =100-(100*I14/J14) -> #DIV/0!
C15: 50 | E15: =D15-B15 -> 0 | F15: 50 | H15: =G15-F15 -> -50 | I15: =E15/C15 -> 0 | J15: =E15/H15 -> 0 | K15: =100-(100*I15/J15) -> #DIV/0!
C16: 50 | E16: =D16-B16 -> 0 | F16: 50 | H16: =G16-F16 -> -50 | I16: =E16/C16 -> 0 | J16: =E16/H16 -> 0 | K16: =100-(100*I16/J16) -> #DIV/0!
C17: 50 | E17: =D17-B17 -> 0 | F17: 50 | H17: =G17-F17 -> -50 | I17: =E17/C17 -> 0 | J17: =E17/H17 -> 0 | K17: =100-(100*I17/J17) -> #DIV/0!
C18: 50 | E18: =D18-B18 -> 0 | F18: 50 | H18: =G18-F18 -> -50 | I18: =E18/C18 -> 0 | J18: =E18/H18 -> 0 | K18: =100-(100*I18/J18) -> #DIV/0!
C19: 50 | E19: =D19-B19 -> 0 | F19: 50 | H19: =G19-F19 -> -50 | I19: =E19/C19 -> 0 | J19: =E19/H19 -> 0 | K19: =100-(100*I19/J19) -> #DIV/0!

Sheet Oven Drying & Combustion
A1: Soil Type | B1: Replicate | C1: Mass Can+Lid | D1: Mass Can+Lid+Soil | E1: Mass Soil | F1: Mass Can+Lid+Soil after 105 C overnight | G1: Mass Soil after 105 C Overnight | H1: gram Water per gram air dry soil | I1: gram Water per gram 105 soil | J1: Mass Can+Lid+Soil after 505 C for 3 Hours | K1: Mass Soil After 505 C overnight | L1: Percent OM per g dehydrated Soil
A2: =Characterization!A2 -> Soybean Undisturbed | B2: 1 | C2: 10.3116 | D2: 11.3148 | E2: =D2-C2 -> 1.0032 | F2: 11.2938 | G2: =F2-C2 -> 0.9822 | H2: =(E2-G2)/E2 -> 0.020933014 | I2: =(E2-G2)/G2 -> 0.021380574 | J2: 11.2147 | K2: =J2-C2 -> 0.9031 | L2: =(G2-K2)/G2 -> 0.080533496
A3: =Characterization!A2 -> Soybean Undisturbed | B3: 2 | C3: 9.841 | D3: 10.9112 | E3: =D3-C3 -> 1.0702 | F3: 10.8891 | G3: =F3-C3 -> 1.0481 | H3: =(E3-G3)/E3 -> 0.020650346 | I3: =(E3-G3)/G3 -> 0.021085774 | J3: 10.8 | K3: =J3-C3 -> 0.959 | L3: =(G3-K3)/G3 -> 0.085010972
A4: =Characterization!A2 -> Soybean Undisturbed | B4: 3 | C4: 10.1114 | D4: 11.1427 | E4: =D4-C4 -> 1.0313 | F4: 11.1223 | G4: =F4-C4 -> 1.0109 | H4: =(E4-G4)/E4 -> 0.019780859 | I4: =(E4-G4)/G4 -> 0.020180038 | J4: 11.0383 | K4: =J4-C4 -> 0.9269 | L4: =(G4-K4)/G4 -> 0.083094272
A5: =Characterization!A3 -> Soybean Center | B5: 1 | C5: 10.9634 | D5: 11.9625 | E5: =D5-C5 -> 0.9991 | F5: 11.9409 | G5: =F5-C5 -> 0.9775 | H5: =(E5-G5)/E5 -> 0.021619458 | I5: =(E5-G5)/G5 -> 0.022097187 | J5: 11.8825 | K5: =J5-C5 -> 0.9191 | L5: =(G5-K5)/G5 -> 0.059744246
A6: =Characterization!A3 -> Soybean Center | B6: 2 | C6: 10.7354 | D6: 11.7112 | E6: =D6-C6 -> 0.9758 | F6: 11.691 | G6: =F6-C6 -> 0.9556 | H6: =(E6-G6)/E6 -> 0.020700963 | I6: =(E6-G6)/G6 -> 0.021138552 | J6: 11.6345 | K6: =J6-C6 -> 0.8991 | L6: =(G6-K6)/G6 -> 0.059125157
A7: =Characterization!A3 -> Soybean Center | B7: 3 | C7: 10.0392 | D7: 11.0834 | E7: =D7-C7 -> 1.0442 | F7: 11.0623 | G7: =F7-C7 -> 1.0231 | H7: =(E7-G7)/E7 -> 0.020206857 | I7: =(E7-G7)/G7 -> 0.020623595 | J7: 11.003 | K7: =J7-C7 -> 0.9638 | L7: =(G7-K7)/G7 -> 0.057961099
A8: =Characterization!A4 -> FGF Rosemary | B8: 1 | C8: 10.7117 | D8: 11.7026 | E8: =D8-C8 -> 0.9909 | F8: 11.6771 | G8: =F8-C8 -> 0.9654 | H8: =(E8-G8)/E8 -> 0.025734181 | I8: =(E8-G8)/G8 -> 0.026413922 | J8: 11.6017 | K8: =J8-C8 -> 0.89 | L8: =(G8-K8)/G8 -> 0.078102341
A9: =Characterization!A4 -> FGF Rosemary | B9: 2 | C9: 10.1225 | D9: 11.1153 | E9: =D9-C9 -> 0.9928 | F9: 11.0894 | G9: =F9-C9 -> 0.9669 | H9: =(E9-G9)/E9 -> 0.026087832 | I9: =(E9-G9)/G9 -> 0.026786638 | J9: 11.0148 | K9: =J9-C9 -> 0.8923 | L9: =(G9-K9)/G9 -> 0.07715379
A10: =Characterization!A4 -> FGF Rosemary | B10: 3 | C10: 9.7612 | D10: 10.7799 | E10: =D10-C10 -> 1.0187 | F10: 10.7527 | G10: =F10-C10 -> 0.9915 | H10: =(E10-G10)/E10 -> 0.026700697 | I10: =(E10-G10)/G10 -> 0.027433182 | J10: 10.6775 | K10: =J10-C10 -> 0.9163 | L10: =(G10-K10)/G10 -> 0.07584468
A11: =Characterization!A5 -> FGF Oregano | B11: 1 | C11: 10.5155 | D11: 11.5417 | E11: =D11-C11 -> 1.0262 | F11: 11.5198 | G11: =F11-C11 -> 1.0043 | H11: =(E11-G11)/E11 -> 0.021340869 | I11: =(E11-G11)/G11 -> 0.021806233 | J11: 11.4513 | K11: =J11-C11 -> 0.9358 | L11: =(G11-K11)/G11 -> 0.068206711
A12: =Characterization!A5 -> FGF Oregano | B12: 2 | C12: 10.589 | D12: 11.5929 | E12: =D12-C12 -> 1.0039 | F12: 11.5727 | G12: =F12-C12 -> 0.9837 | H12: =(E12-G12)/E12 -> 0.020121526 | I12: =(E12-G12)/G12 -> 0.020534716 | J12: 11.5038 | K12: =J12-C12 -> 0.9148 | L12: =(G12-K12)/G12 -> 0.070041679
A13: =Characterization!A5 -> FGF Oregano | B13: 3 | C13: 10.3164 | D13: 11.3066 | E13: =D13-C13 -> 0.9902 | F13: 11.2846 | G13: =F13-C13 -> 0.9682 | H13: =(E13-G13)/E13 -> 0.022217734 | I13: =(E13-G13)/G13 -> 0.022722578 | J13: 11.2189 | K13: =J13-C13 -> 0.9025 | L13: =(G13-K13)/G13 -> 0.067857881
A14: =Characterization!A6 -> FGF Buckwheat | B14: 1 | C14: 9.846 | D14: 10.872 | E14: =D14-C14 -> 1.026 | F14: 10.849 | G14: =F14-C14 -> 1.003 | H14: =(E14-G14)/E14 -> 0.022417154 | I14: =(E14-G14)/G14 -> 0.022931206 | J14: 10.7794 | K14: =J14-C14 -> 0.9334 | L14: =(G14-K14)/G14 -> 0.069391825
A15: =Characterization!A6 -> FGF Buckwheat | B15: 2 | C15: 10.2569 | D15: 11.2855 | E15: =D15-C15 -> 1.0286 | F15: 11.2609 | G15: =F15-C15 -> 1.004 | H15: =(E15-G15)/E15 -> 0.023916002 | I15: =(E15-G15)/G15 -> 0.024501992 | J15: 11.1943 | K15: =J15-C15 -> 0.9374 | L15: =(G15-K15)/G15 -> 0.066334661
A16: =Characterization!A6 -> FGF Buckwheat | B16: 3 | C16: 10.3138 | D16: 11.3316 | E16: =D16-C16 -> 1.0178 | F16: 11.3091 | G16: =F16-C16 -> 0.9953 | H16: =(E16-G16)/E16 -> 0.022106504 | I16: =(E16-G16)/G16 -> 0.022606249 | J16: 11.2418 | K16: =J16-C16 -> 0.928 | L16: =(G16-K16)/G16 -> 0.067617804
A17: =Characterization!A7 -> FGF Sod | B17: 1 | C17: 10.5273 | D17: 11.4508 | E17: =D17-C17 -> 0.9235 | F17: 11.4245 | G17: =F17-C17 -> 0.8972 | H17: =(E17-G17)/E17 -> 0.028478614 | I17: =(E17-G17)/G17 -> 0.02931342 | J17: 11.3224 | K17: =J17-C17 -> 0.7951 | L17: =(G17-K17)/G17 -> 0.11379848
A18: =Characterization!A7 -> FGF Sod | B18: 2 | C18: 10.1955 | D18: 11.25 | E18: =D18-C18 -> 1.0545 | F18: 11.2213 | G18: =F18-C18 -> 1.0258 | H18: =(E18-G18)/E18 -> 0.02721669 | I18: =(E18-G18)/G18 -> 0.027978163 | J18: 11.1023 | K18: =J18-C18 -> 0.9068 | L18: =(G18-K18)/G18 -> 0.11600702
A19: =Characterization!A7 -> FGF Sod | B19: 3 | C19: 10.4476 | D19: 11.5408 | E19: =D19-C19 -> 1.0932 | F19: 11.5094 | G19: =F19-C19 -> 1.0618 | H19: =(E19-G19)/E19 -> 0.028723015 | I19: =(E19-G19)/G19 -> 0.029572424 | J19: 11.3871 | K19: =J19-C19 -> 0.9395 | L19: =(G19-K19)/G19 -> 0.11518177
A20: =Characterization!A8 -> FGF Sunflower | B20: 1 | C20: 10.8154 | D20: 11.8918 | E20: =D20-C20 -> 1.0764 | F20: 11.868 | G20: =F20-C20 -> 1.0526 | H20: =(E20-G20)/E20 -> 0.02211074 | I20: =(E20-G20)/G20 -> 0.022610678 | J20: 11.7933 | K20: =J20-C20 -> 0.9779 | L20: =(G20-K20)/G20 -> 0.070967129
A21: =Characterization!A8 -> FGF Sunflower | B21: 2 | C21: 10.759 | D21: 11.8466 | E21: =D21-C21 -> 1.0876 | F21: 11.8223 | G21: =F21-C21 -> 1.0633 | H21: =(E21-G21)/E21 -> 0.022342773 | I21: =(E21-G21)/G21 -> 0.022853381 | J21: 11.7485 | K21: =J21-C21 -> 0.9895 | L21: =(G21-K21)/G21 -> 0.069406564
A22: =Characterization!A8 -> FGF Sunflower | B22: 3 | C22: 10.2289 | D22: 11.3913 | E22: =D22-C22 -> 1.1624 | F22: 11.3649 | G22: =F22-C22 -> 1.136 | H22: =(E22-G22)/E22 -> 0.022711631 | I22: =(E22-G22)/G22 -> 0.023239437 | J22: 11.2849 | K22: =J22-C22 -> 1.056 | L22: =(G22-K22)/G22 -> 0.070422535
A23: =Characterization!A9 -> FGF Corn | B23: 1 | C23: 10.0923 | D23: 11.2515 | E23: =D23-C23 -> 1.1592 | F23: 11.2267 | G23: =F23-C23 -> 1.1344 | H23: =(E23-G23)/E23 -> 0.021394065 | I23: =(E23-G23)/G23 -> 0.021861777 | J23: 11.1507 | K23: =J23-C23 -> 1.0584 | L23: =(G23-K23)/G23 -> 0.066995769
A24: =Characterization!A9 -> FGF Corn | B24: 2 | C24: 10.1577 | D24: 11.1866 | E24: =D24-C24 -> 1.0289 | F24: 11.1624 | G24: =F24-C24 -> 1.0047 | H24: =(E24-G24)/E24 -> 0.023520264 | I24: =(E24-G24)/G24 -> 0.024086792 | J24: 11.0903 | K24: =J24-C24 -> 0.9326 | L24: =(G24-K24)/G24 -> 0.071762715
A25: =Characterization!A9 -> FGF Corn | B25: 3 | C25: 10.3727 | D25: 11.514 | E25: =D25-C25 -> 1.1413 | F25: 11.487 | G25: =F25-C25 -> 1.1143 | H25: =(E25-G25)/E25 -> 0.023657233 | I25: =(E25-G25)/G25 -> 0.024230459 | J25: 11.4116 | K25: =J25-C25 -> 1.0389 | L25: =(G25-K25)/G25 -> 0.067665799

Sheet Trial Metadata
A1: bottle_id | B1: soil_type | C1: Date of Bottling | D1: Date of Incubation | E1: Length Acclimation (days) | F1: Mass Soil (g) | G1: Mass DNA (g) Soil | H1: WP_mPa | I1: Mass CL (g) | J1: Mass CLS (g) | K1: Mass CLS 105 (g) | L1: (g) Water per (g) 105 soil | M1: Saturation | N1: Mass bottle SOC (g) | O1: Notes
A2: Long-Soy-UD-15-1 | B2: =Characterization!$A$2 -> Soybean Undisturbed | C2: 46036 | D2: 46050 | E2: =_xlfn.DAYS(D2,C2) -> 14 | F2: =2.0077-0.0032 -> 2.0045 | G2: 0.5042 | H2: -9.85 | I2: 10.4305 | J2: 10.9299 | K2: 10.9005 | L2: =(J2-K2)/(K2-I2) -> 0.062553191 | M2: =INDEX(Characterization!M:M, MATCH('Trial Metadata'!B2, Characterization!A:A, 0))*L2/(INDEX(Characterization!O:O, MATCH('Trial Metadata'!B2, Characterization!A:A, 0))*0.01) -> 0.12096825 | N2: =INDEX(Characterization!S:S, MATCH('Trial Metadata'!B2, Characterization!A:A, 0))*F2 -> 0.096356629
A3: Long-Soy-UD-15-2 | B3: =Characterization!$A$2 -> Soybean Undisturbed | C3: 46036 | D3: 46050 | E3: =_xlfn.DAYS(D3,C3) -> 14 | F3: =2.0072-0.0041 -> 2.0031 | G3: 0.516 | H3: -5.27 | I3: 9.5458 | J3: 10.0479 | K3: =I3+10.7337-10.2615 -> 10.018 | L3: =(J3-K3)/(K3-I3) -> 0.063320627 | M3: =INDEX(Characterization!M:M, MATCH('Trial Metadata'!B3, Characterization!A:A, 0))*L3/(INDEX(Characterization!O:O, MATCH('Trial Metadata'!B3, Characterization!A:A, 0))*0.01) -> 0.12245235 | N3: =INDEX(Characterization!S:S, MATCH('Trial Metadata'!B3, Characterization!A:A, 0))*F3 -> 0.096289331
A4: Long-Soy-UD-15-3 | B4: =Characterization!$A$2 -> Soybean Undisturbed | C4: 46036 | D4: 46050 | E4: =_xlfn.DAYS(D4,C4) -> 14 | F4: =2.008-0.0047 -> 2.0033 | G4: 0.5056 | H4: -8.13 | I4: 10.1606 | J4: 10.6753 | K4: 10.6513 | L4: =(J4-K4)/(K4-I4) -> 0.048909721 | M4: =INDEX(Characterization!M:M, MATCH('Trial Metadata'!B4, Characterization!A:A, 0))*L4/(INDEX(Characterization!O:O, MATCH('Trial Metadata'!B4, Characterization!A:A, 0))*0.01) -> 0.094583875 | N4: =INDEX(Characterization!S:S, MATCH('Trial Metadata'!B4, Characterization!A:A, 0))*F4 -> 0.096298945
A5: Long-Soy-UD-25-1 | B5: =Characterization!$A$2 -> Soybean Undisturbed | C5: 46036 | D5: 46050 | E5: =_xlfn.DAYS(D5,C5) -> 14 | F5: =2.004-0.0038 -> 2.0002 | G5: 0.5055 | H5: -5.27 | I5: 10.0318 | J5: 10.437 | K5: 10.4145 | L5: =(J5-K5)/(K5-I5) -> 0.058792788 | M5: =INDEX(Characterization!M:M, MATCH('Trial Metadata'!B5, Characterization!A:A, 0))*L5/(INDEX(Characterization!O:O, MATCH('Trial Metadata'!B5, Characterization!A:A, 0))*0.01) -> 0.11369621 | N5: =INDEX(Characterization!S:S, MATCH('Trial Metadata'!B5, Characterization!A:A, 0))*F5 -> 0.096149927
A6: Long-Soy-UD-25-2 | B6: =Characterization!$A$2 -> Soybean Undisturbed | C6: 46036 | D6: 46050 | E6: =_xlfn.DAYS(D6,C6) -> 14 | F6: =2.0073-0.005 -> 2.0023 | G6: 0.5002 | H6: -1.19 | I6: =10.3875 -> 10.3875 | J6: 10.8912 | K6: 10.8536 | L6: =(J6-K6)/(K6-I6) -> 0.080669384 | M6: =INDEX(Characterization!M:M, MATCH('Trial Metadata'!B6, Characterization!A:A, 0))*L6/(INDEX(Characterization!O:O, MATCH('Trial Metadata'!B6, Characterization!A:A, 0))*0.01) -> 0.15600218 | N6: =INDEX(Characterization!S:S, MATCH('Trial Metadata'!B6, Characterization!A:A, 0))*F6 -> 0.096250875
A7: Long-Soy-UD-25-3 | B7: =Characterization!$A$2 -> Soybean Undisturbed | C7: 46036 | D7: 46050 | E7: =_xlfn.DAYS(D7,C7) -> 14 | F7: =2.0074-0.0049 -> 2.0025 | G7: 0.5047 | H7: -1.89 | I7: 10.322 | J7: 10.766 | K7: 10.7325 | L7: =(J7-K7)/(K7-I7) -> 0.081607795 | M7: =INDEX(Characterization!M:M, MATCH('Trial Metadata'!B7, Characterization!A:A, 0))*L7/(INDEX(Characterization!O:O, MATCH('Trial Metadata'!B7, Characterization!A:A, 0))*0.01) -> 0.15781692 | N7: =INDEX(Characterization!S:S, MATCH('Trial Metadata'!B7, Characterization!A:A, 0))*F7 -> 0.096260489
A8: Long-Soy-C-25-1 | B8: =Characterization!$A$3 -> Soybean Center | C8: 46049 | D8: 46065 | E8: =_xlfn.DAYS(D8,C8) -> 16 | F8: =2.0044-0.0043 -> 2.0001 | G8: 0.4868 | H8: -122.78 | I8: 10.2818 | J8: 10.8318 | K8: 10.8091 | L8: =(J8-K8)/(K8-I8) -> 0.043049497 | M8: =INDEX(Characterization!M:M, MATCH('Trial Metadata'!B8, Characterization!A:A, 0))*L8/(INDEX(Characterization!O:O, MATCH('Trial Metadata'!B8, Characterization!A:A, 0))*0.01) -> 0.10107663 | N8: =INDEX(Characterization!S:S, MATCH('Trial Metadata'!B8, Characterization!A:A, 0))*F8 -> 0.068377879 | O8: Broken Rim
A9: Long-Soy-C-25-2 | B9: =Characterization!$A$3 -> Soybean Center | C9: 46049 | D9: 46065 | E9: =_xlfn.DAYS(D9,C9) -> 16 | F9: =2.0053-0.0049 -> 2.0004 | G9: 0.5037 | H9: -34.76 | I9: 10.461 | J9: 11.0146 | K9: 10.9834 | L9: =(J9-K9)/(K9-I9) -> 0.059724349 | M9: =INDEX(Characterization!M:M, MATCH('Trial Metadata'!B9, Characterization!A:A, 0))*L9/(INDEX(Characterization!O:O, MATCH('Trial Metadata'!B9, Characterization!A:A, 0))*0.01) -> 0.14022779 | N9: =INDEX(Characterization!S:S, MATCH('Trial Metadata'!B9, Characterization!A:A, 0))*F9 -> 0.068388135
A10: Long-Soy-C-25-3 | B10: =Characterization!$A$3 -> Soybean Center | C10: 46049 | D10: 46065 | E10: =_xlfn.DAYS(D10,C10) -> 16 | F10: =2.0046-0.0046 -> 2 | G10: 0.4983 | H10: -59.35 | I10: 10.0842 | J10: 10.5789 | K10: 10.5703 | L10: =(J10-K10)/(K10-I10) -> 0.017691833 | M10: =INDEX(Characterization!M:M, MATCH('Trial Metadata'!B10, Characterization!A:A, 0))*L10/(INDEX(Characterization!O:O, MATCH('Trial Metadata'!B10, Characterization!A:A, 0))*0.01) -> 0.041538949 | N10: =INDEX(Characterization!S:S, MATCH('Trial Metadata'!B10, Characterization!A:A, 0))*F10 -> 0.06837446 | O10: Crack before start
A11: Long-Soy-C-15-1 | B11: =Characterization!$A$3 -> Soybean Center | C11: 46049 | D11: 46065 | E11: =_xlfn.DAYS(D11,C11) -> 16 | F11: =2.0031-0.0014 -> 2.0017 | G11: 0.5007 | H11: -68.35 | I11: 10.7195 | J11: 11.236 | K11: 11.2259 | L11: =(J11-K11)/(K11-I11) -> 0.019944708 | M11: =INDEX(Characterization!M:M, MATCH('Trial Metadata'!B11, Characterization!A:A, 0))*L11/(INDEX(Characterization!O:O, MATCH('Trial Metadata'!B11, Characterization!A:A, 0))*0.01) -> 0.046828512 | N11: =INDEX(Characterization!S:S, MATCH('Trial Metadata'!B11, Characterization!A:A, 0))*F11 -> 0.068432579 | O11: Crack before start
A12: Long-Soy-C-15-2 | B12: =Characterization!$A$3 -> Soybean Center | C12: 46049 | D12: 46065 | E12: =_xlfn.DAYS(D12,C12) -> 16 | F12: =2.008-0.002 -> 2.006 | G12: 0.4842 | H12: -47.12 | I12: 9.8863 | J12: 10.4278 | K12: 10.4108 | L12: =(J12-K12)/(K12-I12) -> 0.032411821 | M12: =INDEX(Characterization!M:M, MATCH('Trial Metadata'!B12, Characterization!A:A, 0))*L12/(INDEX(Characterization!O:O, MATCH('Trial Metadata'!B12, Characterization!A:A, 0))*0.01) -> 0.076100254 | N12: =INDEX(Characterization!S:S, MATCH('Trial Metadata'!B12, Characterization!A:A, 0))*F12 -> 0.068579584
A13: Long-Soy-C-15-3 | B13: =Characterization!$A$3 -> Soybean Center | C13: 46049 | D13: 46065 | E13: =_xlfn.DAYS(D13,C13) -> 16 | F13: =2.0041-0.0035 -> 2.0006 | G13: 0.5073 | H13: -114.39 | I13: 10.1607 | J13: 10.6844 | K13: 10.6685 | L13: =(J13-K13)/(K13-I13) -> 0.03131154 | M13: =INDEX(Characterization!M:M, MATCH('Trial Metadata'!B13, Characterization!A:A, 0))*L13/(INDEX(Characterization!O:O, MATCH('Trial Metadata'!B13, Characterization!A:A, 0))*0.01) -> 0.073516887 | N13: =INDEX(Characterization!S:S, MATCH('Trial Metadata'!B13, Characterization!A:A, 0))*F13 -> 0.068394973
A14: Short-Soy-UD-15-1 | B14: =Characterization!$A$2 -> Soybean Undisturbed | C14: 46086 | D14: 46090 | E14: =_xlfn.DAYS(D14,C14) -> 4 | F14: =2.0065-0.0019 -> 2.0046 | G14: 0.4987 | H14: -9.03 | I14: 10.1005 | J14: 10.6864 | K14: 10.6613 | L14: =(J14-K14)/(K14-I14) -> 0.044757489 | M14: =INDEX(Characterization!M:M, MATCH('Trial Metadata'!B14, Characterization!A:A, 0))*L14/(INDEX(Characterization!O:O, MATCH('Trial Metadata'!B14, Characterization!A:A, 0))*0.01) -> 0.086554099 | N14: =INDEX(Characterization!S:S, MATCH('Trial Metadata'!B14, Characterization!A:A, 0))*F14 -> 0.096361436 | O14: Bottle Broke at End, glass in saturation can maybe?
A15: Short-Soy-UD-15-2 | B15: =Characterization!$A$2 -> Soybean Undisturbed | C15: 46086 | D15: 46090 | E15: =_xlfn.DAYS(D15,C15) -> 4 | F15: =2.0086-0.0016 -> 2.007 | G15: 0.4817 | H15: -5.18 | I15: 10.0471 | J15: 10.5988 | K15: 10.5705 | L15: =(J15-K15)/(K15-I15) -> 0.054069545 | M15: =INDEX(Characterization!M:M, MATCH('Trial Metadata'!B15, Characterization!A:A, 0))*L15/(INDEX(Characterization!O:O, MATCH('Trial Metadata'!B15, Characterization!A:A, 0))*0.01) -> 0.10456218 | N15: =INDEX(Characterization!S:S, MATCH('Trial Metadata'!B15, Characterization!A:A, 0))*F15 -> 0.096476804
A16: Short-Soy-UD-15-3 | B16: =Characterization!$A$2 -> Soybean Undisturbed | C16: 46086 | D16: 46090 | E16: =_xlfn.DAYS(D16,C16) -> 4 | F16: =2.0077-0.0016 -> 2.0061 | G16: 0.4708 | H16: -5.78 | I16: 10.2785 | J16: 10.8237 | K16: 10.7981 | L16: =(J16-K16)/(K16-I16) -> 0.049268668 | M16: =INDEX(Characterization!M:M, MATCH('Trial Metadata'!B16, Characterization!A:A, 0))*L16/(INDEX(Characterization!O:O, MATCH('Trial Metadata'!B16, Characterization!A:A, 0))*0.01) -> 0.095278025 | N16: =INDEX(Characterization!S:S, MATCH('Trial Metadata'!B16, Characterization!A:A, 0))*F16 -> 0.096433541
A17: Short-Soy-UD-25-1 | B17: =Characterization!$A$2 -> Soybean Undisturbed | C17: 46086 | D17: 46090 | E17: =_xlfn.DAYS(D17,C17) -> 4 | F17: =2.003-0.0015 -> 2.0015 | G17: 0.5052 | H17: -1.16 | I17: 10.3347 | J17: 10.9281 | K17: 10.8734 | L17: =(J17-K17)/(K17-I17) -> 0.10154075 | M17: =INDEX(Characterization!M:M, MATCH('Trial Metadata'!B17, Characterization!A:A, 0))*L17/(INDEX(Characterization!O:O, MATCH('Trial Metadata'!B17, Characterization!A:A, 0))*0.01) -> 0.19636418 | N17: =INDEX(Characterization!S:S, MATCH('Trial Metadata'!B17, Characterization!A:A, 0))*F17 -> 0.096212418
A18: Short-Soy-UD-25-2 | B18: =Characterization!$A$2 -> Soybean Undisturbed | C18: 46086 | D18: 46090 | E18: =_xlfn.DAYS(D18,C18) -> 4 | F18: =2.0087-0.0028 -> 2.0059 | G18: 0.5027 | H18: -1.48 | I18: 10.8227 | J18: 11.4642 | K18: 11.4079 | L18: =(J18-K18)/(K18-I18) -> 0.096206425 | M18: =INDEX(Characterization!M:M, MATCH('Trial Metadata'!B18, Characterization!A:A, 0))*L18/(INDEX(Characterization!O:O, MATCH('Trial Metadata'!B18, Characterization!A:A, 0))*0.01) -> 0.18604843 | N18: =INDEX(Characterization!S:S, MATCH('Trial Metadata'!B18, Characterization!A:A, 0))*F18 -> 0.096423927
A19: Short-Soy-UD-25-3 | B19: =Characterization!$A$2 -> Soybean Undisturbed | C19: 46086 | D19: 46090 | E19: =_xlfn.DAYS(D19,C19) -> 4 | F19: =2.0026-0.001 -> 2.0016 | G19: 0.5093 | H19: -1.66 | I19: 10.011 | J19: 10.5215 | K19: 10.4858 | L19: =(J19-K19)/(K19-I19) -> 0.075189553 | M19: =INDEX(Characterization!M:M, MATCH('Trial Metadata'!B19, Characterization!A:A, 0))*L19/(INDEX(Characterization!O:O, MATCH('Trial Metadata'!B19, Characterization!A:A, 0))*0.01) -> 0.14540503 | N19: =INDEX(Characterization!S:S, MATCH('Trial Metadata'!B19, Characterization!A:A, 0))*F19 -> 0.096217225 | O19: No Crack I don't think…
A20: Short-Soy-C-15-1 | B20: =Characterization!$A$3 -> Soybean Center | C20: 46087 | D20: 46091 | E20: =_xlfn.DAYS(D20,C20) -> 4 | F20: =2.0038-0.0014 -> 2.0024 | G20: 0.496 | H20: -5.72 | I20: 10.6744 | J20: 11.2348 | K20: 11.2096 | L20: =(J20-K20)/(K20-I20) -> 0.047085202 | M20: =INDEX(Characterization!M:M, MATCH('Trial Metadata'!B20, Characterization!A:A, 0))*L20/(INDEX(Characterization!O:O, MATCH('Trial Metadata'!B20, Characterization!A:A, 0))*0.01) -> 0.11055213 | N20: =INDEX(Characterization!S:S, MATCH('Trial Metadata'!B20, Characterization!A:A, 0))*F20 -> 0.06845651
A21: Short-Soy-C-15-2 | B21: =Characterization!$A$3 -> Soybean Center | C21: 46087 | D21: 46091 | E21: =_xlfn.DAYS(D21,C21) -> 4 | F21: =2.0057-0.0015 -> 2.0042 | G21: 0.4977 | H21: -6.49 | I21: 10.7262 | J21: 11.282 | K21: 11.2594 | L21: =(J21-K21)/(K21-I21) -> 0.042385596 | M21: =INDEX(Characterization!M:M, MATCH('Trial Metadata'!B21, Characterization!A:A, 0))*L21/(INDEX(Characterization!O:O, MATCH('Trial Metadata'!B21, Characterization!A:A, 0))*0.01) -> 0.099517848 | N21: =INDEX(Characterization!S:S, MATCH('Trial Metadata'!B21, Characterization!A:A, 0))*F21 -> 0.068518047
A22: Short-Soy-C-15-3 | B22: =Characterization!$A$3 -> Soybean Center | C22: 46087 | D22: 46091 | E22: =_xlfn.DAYS(D22,C22) -> 4 | F22: =2.0055-0.0019 -> 2.0036 | G22: 0.4856 | H22: -11.78 | I22: 10.3577 | J22: 10.9011 | K22: 10.8789 | L22: =(J22-K22)/(K22-I22) -> 0.042594014 | M22: =INDEX(Characterization!M:M, MATCH('Trial Metadata'!B22, Characterization!A:A, 0))*L22/(INDEX(Characterization!O:O, MATCH('Trial Metadata'!B22, Characterization!A:A, 0))*0.01) -> 0.10000719 | N22: =INDEX(Characterization!S:S, MATCH('Trial Metadata'!B22, Characterization!A:A, 0))*F22 -> 0.068497534
A23: Short-Soy-C-25-1 | B23: =Characterization!$A$3 -> Soybean Center | C23: 46087 | D23: 46091 | E23: =_xlfn.DAYS(D23,C23) -> 4 | F23: =2.008-0.0022 -> 2.0058 | G23: 0.4907 | H23: -0.83 | I23: 10.2479 | J23: 10.8115 | K23: 10.751 | L23: =(J23-K23)/(K23-I23) -> 0.12025442 | M23: =INDEX(Characterization!M:M, MATCH('Trial Metadata'!B23, Characterization!A:A, 0))*L23/(INDEX(Characterization!O:O, MATCH('Trial Metadata'!B23, Characterization!A:A, 0))*0.01) -> 0.28234736 | N23: =INDEX(Characterization!S:S, MATCH('Trial Metadata'!B23, Characterization!A:A, 0))*F23 -> 0.068572746
A24: Short-Soy-C-25-2 | B24: =Characterization!$A$3 -> Soybean Center | C24: 46087 | D24: 46091 | E24: =_xlfn.DAYS(D24,C24) -> 4 | F24: =2.0092-0.0022 -> 2.007 | G24: 0.5036 | H24: -1.36 | I24: 10.2066 | J24: 10.7446 | K24: 10.7016 | L24: =(J24-K24)/(K24-I24) -> 0.086868687 | M24: =INDEX(Characterization!M:M, MATCH('Trial Metadata'!B24, Characterization!A:A, 0))*L24/(INDEX(Characterization!O:O, MATCH('Trial Metadata'!B24, Characterization!A:A, 0))*0.01) -> 0.20396044 | N24: =INDEX(Characterization!S:S, MATCH('Trial Metadata'!B24, Characterization!A:A, 0))*F24 -> 0.068613771
A25: Short-Soy-C-25-3 | B25: =Characterization!$A$3 -> Soybean Center | C25: 46087 | D25: 46091 | E25: =_xlfn.DAYS(D25,C25) -> 4 | F25: 2.0055 | G25: 0.4921 | H25: -3.92 | I25: 10.196 | J25: 10.7335 | K25: 10.7031 | L25: =(J25-K25)/(K25-I25) -> 0.059948728 | M25: =INDEX(Characterization!M:M, MATCH('Trial Metadata'!B25, Characterization!A:A, 0))*L25/(INDEX(Characterization!O:O, MATCH('Trial Metadata'!B25, Characterization!A:A, 0))*0.01) -> 0.14075462 | N25: =INDEX(Characterization!S:S, MATCH('Trial Metadata'!B25, Characterization!A:A, 0))*F25 -> 0.06856249 | O25: Cracked Bottom
A26: FGF-OR-15-1 | B26: FGF Oregano | C26: 46091 | D26: 46095 | E26: =_xlfn.DAYS(D26,C26) -> 4 | F26: =2.0076-0.0031 -> 2.0045 | G26: 0.4992 | H26: -29.15 | I26: 9.9129 | J26: 10.4349 | K26: 10.4188 | L26: =(J26-K26)/(K26-I26) -> 0.031824471 | M26: =INDEX(Characterization!M:M, MATCH('Trial Metadata'!B26, Characterization!A:A, 0))*L26/(INDEX(Characterization!O:O, MATCH('Trial Metadata'!B26, Characterization!A:A, 0))*0.01) -> 0.095443105 | N26: =INDEX(Characterization!S:S, MATCH('Trial Metadata'!B26, Characterization!A:A, 0))*F26 -> 0.079873737 | O26: SO SLOW
A27: FGF-OR-15-2 | B27: FGF Oregano | C27: 46091 | D27: 46095 | E27: =_xlfn.DAYS(D27,C27) -> 4 | F27: =2.0015-0.0026 -> 1.9989 | G27: 0.4978 | H27: -42.2 | I27: 10.4463 | J27: 10.9688 | K27: 10.9538 | L27: =(J27-K27)/(K27-I27) -> 0.02955665 | M27: =INDEX(Characterization!M:M, MATCH('Trial Metadata'!B27, Characterization!A:A, 0))*L27/(INDEX(Characterization!O:O, MATCH('Trial Metadata'!B27, Characterization!A:A, 0))*0.01) -> 0.088641802 | N27: =INDEX(Characterization!S:S, MATCH('Trial Metadata'!B27, Characterization!A:A, 0))*F27 -> 0.079650593 | O27: SO SLOW
A28: FGF-OR-15-3 | B28: FGF Oregano | C28: 46091 | D28: 46095 | E28: =_xlfn.DAYS(D28,C28) -> 4 | F28: =2.0057-0.0022 -> 2.0035 | G28: 0.5091 | H28: -22.68 | I28: 10.026 | J28: 10.5181 | K28: 10.5007 | L28: =(J28-K28)/(K28-I28) -> 0.036654729 | M28: =INDEX(Characterization!M:M, MATCH('Trial Metadata'!B28, Characterization!A:A, 0))*L28/(INDEX(Characterization!O:O, MATCH('Trial Metadata'!B28, Characterization!A:A, 0))*0.01) -> 0.10992928 | N28: =INDEX(Characterization!S:S, MATCH('Trial Metadata'!B28, Characterization!A:A, 0))*F28 -> 0.07983389 | O28: SO SLOW
A29: FGF-OR-25-1 | B29: FGF Oregano | C29: 46091 | D29: 46095 | E29: =_xlfn.DAYS(D29,C29) -> 4 | F29: =2.0084-0.0031 -> 2.0053 | G29: 0.5082 | H29: -8 | I29: 11.6901 | J29: 12.2092 | K29: 12.1809 | L29: =(J29-K29)/(K29-I29) -> 0.057660962 | M29: =INDEX(Characterization!M:M, MATCH('Trial Metadata'!B29, Characterization!A:A, 0))*L29/(INDEX(Characterization!O:O, MATCH('Trial Metadata'!B29, Characterization!A:A, 0))*0.01) -> 0.17292797 | N29: =INDEX(Characterization!S:S, MATCH('Trial Metadata'!B29, Characterization!A:A, 0))*F29 -> 0.079905615
A30: FGF-OR-25-2 | B30: FGF Oregano | C30: 46091 | D30: 46095 | E30: =_xlfn.DAYS(D30,C30) -> 4 | F30: =2.005-0.0032 -> 2.0018 | G30: 0.4993 | H30: -8.54 | I30: 11.7432 | J30: 12.2882 | K30: 12.2626 | L30: =(J30-K30)/(K30-I30) -> 0.04928764 | M30: =INDEX(Characterization!M:M, MATCH('Trial Metadata'!B30, Characterization!A:A, 0))*L30/(INDEX(Characterization!O:O, MATCH('Trial Metadata'!B30, Characterization!A:A, 0))*0.01) -> 0.14781598 | N30: =INDEX(Characterization!S:S, MATCH('Trial Metadata'!B30, Characterization!A:A, 0))*F30 -> 0.07976615 | O30: WPA maybe -8.45? Forgor
A31: FGF-OR-25-3 | B31: FGF Oregano | C31: 46091 | D31: 46095 | E31: =_xlfn.DAYS(D31,C31) -> 4 | F31: =2.0053-0.0036 -> 2.0017 | G31: 0.4978 | H31: -3.74 | I31: 11.7173 | J31: 12.2337 | K31: 12.2058 | L31: =(J31-K31)/(K31-I31) -> 0.057113613 | M31: =INDEX(Characterization!M:M, MATCH('Trial Metadata'!B31, Characterization!A:A, 0))*L31/(INDEX(Characterization!O:O, MATCH('Trial Metadata'!B31, Characterization!A:A, 0))*0.01) -> 0.17128645 | N31: =INDEX(Characterization!S:S, MATCH('Trial Metadata'!B31, Characterization!A:A, 0))*F31 -> 0.079762165
A32: FGF-RO-15-1 | B32: FGF Rosemary | C32: 46092 | D32: 46096 | E32: =_xlfn.DAYS(D32,C32) -> 4 | F32: =2.0056-0.0022 -> 2.0034 | G32: 0.5082 | H32: -26.42 | I32: 10.7102 | J32: 11.2226 | K32: 11.2075 | L32: =(J32-K32)/(K32-I32) -> 0.030363965 | M32: =INDEX(Characterization!M:M, MATCH('Trial Metadata'!B32, Characterization!A:A, 0))*L32/(INDEX(Characterization!O:O, MATCH('Trial Metadata'!B32, Characterization!A:A, 0))*0.01) -> 0.087144581 | N32: =INDEX(Characterization!S:S, MATCH('Trial Metadata'!B32, Characterization!A:A, 0))*F32 -> 0.089510891
A33: FGF-RO-15-2 | B33: FGF Rosemary | C33: 46092 | D33: 46096 | E33: =_xlfn.DAYS(D33,C33) -> 4 | F33: =2.0052-0.0037 -> 2.0015 | G33: 0.4949 | H33: -22.36 | I33: 10.152 | J33: 10.6524 | K33: 10.6367 | L33: =(J33-K33)/(K33-I33) -> 0.03239117 | M33: =INDEX(Characterization!M:M, MATCH('Trial Metadata'!B33, Characterization!A:A, 0))*L33/(INDEX(Characterization!O:O, MATCH('Trial Metadata'!B33, Characterization!A:A, 0))*0.01) -> 0.092962657 | N33: =INDEX(Characterization!S:S, MATCH('Trial Metadata'!B33, Characterization!A:A, 0))*F33 -> 0.089426
A34: FGF-RO-15-3 | B34: FGF Rosemary | C34: 46092 | D34: 46096 | E34: =_xlfn.DAYS(D34,C34) -> 4 | F34: =2.0048-0.0038 -> 2.001 | G34: 0.5088 | H34: -19.76 | I34: 9.8387 | J34: 10.3431 | K34: 10.3252 | L34: =(J34-K34)/(K34-I34) -> 0.036793422 | M34: =INDEX(Characterization!M:M, MATCH('Trial Metadata'!B34, Characterization!A:A, 0))*L34/(INDEX(Characterization!O:O, MATCH('Trial Metadata'!B34, Characterization!A:A, 0))*0.01) -> 0.10559712 | N34: =INDEX(Characterization!S:S, MATCH('Trial Metadata'!B34, Characterization!A:A, 0))*F34 -> 0.08940366 | O34: WP may be wrong, number slipped mind (but I think it was -19.something)
A35: FGF-RO-25-1 | B35: FGF Rosemary | C35: 46092 | D35: 46096 | E35: =_xlfn.DAYS(D35,C35) -> 4 | F35: =2.0058-0.0051 -> 2.0007 | G35: 0.4922 | H35: -5.71 | I35: 10.2281 | J35: 10.8008 | K35: 10.7689 | L35: =(J35-K35)/(K35-I35) -> 0.058986686 | M35: =INDEX(Characterization!M:M, MATCH('Trial Metadata'!B35, Characterization!A:A, 0))*L35/(INDEX(Characterization!O:O, MATCH('Trial Metadata'!B35, Characterization!A:A, 0))*0.01) -> 0.16929179 | N35: =INDEX(Characterization!S:S, MATCH('Trial Metadata'!B35, Characterization!A:A, 0))*F35 -> 0.089390256
A36: FGF-RO-25-2 | B36: FGF Rosemary | C36: 46092 | D36: 46096 | E36: =_xlfn.DAYS(D36,C36) -> 4 | F36: =2.0044-0.0053 -> 1.9991 | G36: 0.501 | H36: -6.5 | I36: 10.6739 | J36: 11.2195 | K36: 11.1878 | L36: =(J36-K36)/(K36-I36) -> 0.061685153 | M36: =INDEX(Characterization!M:M, MATCH('Trial Metadata'!B36, Characterization!A:A, 0))*L36/(INDEX(Characterization!O:O, MATCH('Trial Metadata'!B36, Characterization!A:A, 0))*0.01) -> 0.17703639 | N36: =INDEX(Characterization!S:S, MATCH('Trial Metadata'!B36, Characterization!A:A, 0))*F36 -> 0.089318769
A37: FGF-RO-25-3 | B37: FGF Rosemary | C37: 46092 | D37: 46096 | E37: =_xlfn.DAYS(D37,C37) -> 4 | F37: =2.0036-0.0056 -> 1.998 | G37: 0.503 | H37: -4.87 | I37: 10.5348 | J37: 11.0832 | K37: 11.0505 | L37: =(J37-K37)/(K37-I37) -> 0.063408959 | M37: =INDEX(Characterization!M:M, MATCH('Trial Metadata'!B37, Characterization!A:A, 0))*L37/(INDEX(Characterization!O:O, MATCH('Trial Metadata'!B37, Characterization!A:A, 0))*0.01) -> 0.18198371 | N37: =INDEX(Characterization!S:S, MATCH('Trial Metadata'!B37, Characterization!A:A, 0))*F37 -> 0.089269621
A38: FGF-SOD-15-1 | B38: FGF Sod | C38: 46096 | D38: 46099 | E38: =_xlfn.DAYS(D38,C38) -> 3 | F38: =2.0078-0.004 -> 2.0038 | G38: 0.4938 | H38: -29.42 | I38: 10.3694 | J38: 10.8992 | K38: 10.8707 | L38: =(J38-K38)/(K38-I38) -> 0.056852184 | M38: =INDEX(Characterization!M:M, MATCH('Trial Metadata'!B38, Characterization!A:A, 0))*L38/(INDEX(Characterization!O:O, MATCH('Trial Metadata'!B38, Characterization!A:A, 0))*0.01) -> 0.12152154 | N38: =INDEX(Characterization!S:S, MATCH('Trial Metadata'!B38, Characterization!A:A, 0))*F38 -> 0.13364853
A39: FGF-SOD-15-2 | B39: FGF Sod | C39: 46096 | D39: 46099 | E39: =_xlfn.DAYS(D39,C39) -> 3 | F39: =2.0046-0.0031 -> 2.0015 | G39: 0.5029 | H39: -25.4 | I39: 10.3938 | J39: 10.9028 | K39: 10.8775 | L39: =(J39-K39)/(K39-I39) -> 0.052305148 | M39: =INDEX(Characterization!M:M, MATCH('Trial Metadata'!B39, Characterization!A:A, 0))*L39/(INDEX(Characterization!O:O, MATCH('Trial Metadata'!B39, Characterization!A:A, 0))*0.01) -> 0.11180225 | N39: =INDEX(Characterization!S:S, MATCH('Trial Metadata'!B39, Characterization!A:A, 0))*F39 -> 0.13349512
A40: FGF-SOD-15-3 | B40: FGF Sod | C40: 46096 | D40: 46099 | E40: =_xlfn.DAYS(D40,C40) -> 3 | F40: =2.0049-0.0023 -> 2.0026 | G40: 0.5029 | H40: -18.5 | I40: 10.099 | J40: 10.6288 | K40: 10.6011 | L40: =(J40-K40)/(K40-I40) -> 0.055168293 | M40: =INDEX(Characterization!M:M, MATCH('Trial Metadata'!B40, Characterization!A:A, 0))*L40/(INDEX(Characterization!O:O, MATCH('Trial Metadata'!B40, Characterization!A:A, 0))*0.01) -> 0.11792223 | N40: =INDEX(Characterization!S:S, MATCH('Trial Metadata'!B40, Characterization!A:A, 0))*F40 -> 0.13356849
...

Sheet DNA Samples for Sequencing
A1: Sample # (on Cap) | B1: Date | C1: Name | D1: Sample Name | E1: Sample Name Underscores | F1: Correct NanoDrop DNA Conc (ng/ul) | G1: *OLD* NanoDrop DNA conc (ng/uL) | H1: Notes
A2: 1 | B2: 45856 | C2: FGF-SF-20-1 | D2: =CONCATENATE(ROW(B2)-1,"-",TEXT(B2, "mm-dd-yyyy"),"-",C2) -> 1-07-18-2025-FGF-SF-20-1 | E2: =SUBSTITUTE(D2,"-","_") -> 1_07_18_2025_FGF_SF_20_1 | F2: 148.1 | G2: 149 | H2: 147.3 redo, 141.1 redo 2, 137.3 redo 3 | I2: Wrong name in nanodrop: | J2: FGF-RM-20-1
A3: 2 | B3: 45856 | C3: FGF-SF-20-2 | D3: =CONCATENATE(ROW(B3)-1,"-",TEXT(B3, "mm-dd-yyyy"),"-",C3) -> 2-07-18-2025-FGF-SF-20-2 | E3: =SUBSTITUTE(D3,"-","_") -> 2_07_18_2025_FGF_SF_20_2 | F3: 132.7 | G3: 134.3 | I3: Wrong name in nanodrop: | J3: FGF-RM-20-2
A4: 3 | B4: 45856 | C4: FGF-SF-20-3 | D4: =CONCATENATE(ROW(B4)-1,"-",TEXT(B4, "mm-dd-yyyy"),"-",C4) -> 3-07-18-2025-FGF-SF-20-3 | E4: =SUBSTITUTE(D4,"-","_") -> 3_07_18_2025_FGF_SF_20_3 | F4: 171.9 | G4: 171.6 | I4: Wrong name in nanodrop: | J4: FGF-RM-20-3
A5: 4 | B5: 45860 | C5: FGF-RM-20-1 | D5: =CONCATENATE(ROW(B5)-1,"-",TEXT(B5, "mm-dd-yyyy"),"-",C5) -> 4-07-22-2025-FGF-RM-20-1 | E5: =SUBSTITUTE(D5,"-","_") -> 4_07_22_2025_FGF_RM_20_1 | F5: 287.7 | G5: 276 | I5: Wrong name in nanodrop: | J5: FGF-SF-20-1
A6: 5 | B6: 45860 | C6: FGF-RM-20-2 | D6: =CONCATENATE(ROW(B6)-1,"-",TEXT(B6, "mm-dd-yyyy"),"-",C6) -> 5-07-22-2025-FGF-RM-20-2 | E6: =SUBSTITUTE(D6,"-","_") -> 5_07_22_2025_FGF_RM_20_2 | F6: 280.7 | G6: 458.2 | H6: 287.7 redo | I6: Wrong name in nanodrop: | J6: FGF-SF-20-2
A7: 6 | B7: 45860 | C7: FGF-RM-20-3 | D7: =CONCATENATE(ROW(B7)-1,"-",TEXT(B7, "mm-dd-yyyy"),"-",C7) -> 6-07-22-2025-FGF-RM-20-3 | E7: =SUBSTITUTE(D7,"-","_") -> 6_07_22_2025_FGF_RM_20_3 | F7: 271.1 | G7: 323.7 | H7: 462.5 redo | I7: Wrong name in nanodrop: | J7: FGF-SF-20-3
A8: 7 | B8: 45856 | C8: FGF-CO-20-1 | D8: =CONCATENATE(ROW(B8)-1,"-",TEXT(B8, "mm-dd-yyyy"),"-",C8) -> 7-07-18-2025-FGF-CO-20-1 | E8: =SUBSTITUTE(D8,"-","_") -> 7_07_18_2025_FGF_CO_20_1 | F8: 245.2 | G8: 540.9 | H8: 234.5 redo
A9: 8 | B9: 45856 | C9: FGF-CO-20-2 | D9: =CONCATENATE(ROW(B9)-1,"-",TEXT(B9, "mm-dd-yyyy"),"-",C9) -> 8-07-18-2025-FGF-CO-20-2 | E9: =SUBSTITUTE(D9,"-","_") -> 8_07_18_2025_FGF_CO_20_2 | F9: 201.9 | G9: 180.2 | H9: 174.5 upon redo
A10: 9 | B10: 45856 | C10: FGF-CO-20-3 | D10: =CONCATENATE(ROW(B10)-1,"-",TEXT(B10, "mm-dd-yyyy"),"-",C10) -> 9-07-18-2025-FGF-CO-20-3 | E10: =SUBSTITUTE(D10,"-","_") -> 9_07_18_2025_FGF_CO_20_3 | F10: 182.4 | G10: 198.9
A11: 10 | B11: 45860 | C11: FGF-OR-20-1 | D11: =CONCATENATE(ROW(B11)-1,"-",TEXT(B11, "mm-dd-yyyy"),"-",C11) -> 10-07-22-2025-FGF-OR-20-1 | E11: =SUBSTITUTE(D11,"-","_") -> 10_07_22_2025_FGF_OR_20_1 | F11: 197 | G11: 186.6
A12: 11 | B12: 45860 | C12: FGF-OR-20-2 | D12: =CONCATENATE(ROW(B12)-1,"-",TEXT(B12, "mm-dd-yyyy"),"-",C12) -> 11-07-22-2025-FGF-OR-20-2 | E12: =SUBSTITUTE(D12,"-","_") -> 11_07_22_2025_FGF_OR_20_2 | F12: 172.2 | G12: 212.1
A13: 12 | B13: 45860 | C13: FGF-OR-20-3 | D13: =CONCATENATE(ROW(B13)-1,"-",TEXT(B13, "mm-dd-yyyy"),"-",C13) -> 12-07-22-2025-FGF-OR-20-3 | E13: =SUBSTITUTE(D13,"-","_") -> 12_07_22_2025_FGF_OR_20_3 | F13: 246.1 | G13: 230.8
A14: 13 | B14: 45862 | C14: FGF-SOD-20-1 | D14: =CONCATENATE(ROW(B14)-1,"-",TEXT(B14, "mm-dd-yyyy"),"-",C14) -> 13-07-24-2025-FGF-SOD-20-1 | E14: =SUBSTITUTE(D14,"-","_") -> 13_07_24_2025_FGF_SOD_20_1 | F14: 619.8 | G14: 1009.2 | H14: 758.3 upon redo, 596.4 redo again, 619.7 redo again
A15: 14 | B15: 45862 | C15: FGF-SOD-20-2 | D15: =CONCATENATE(ROW(B15)-1,"-",TEXT(B15, "mm-dd-yyyy"),"-",C15) -> 14-07-24-2025-FGF-SOD-20-2 | E15: =SUBSTITUTE(D15,"-","_") -> 14_07_24_2025_FGF_SOD_20_2 | F15: 671.8 | G15: 1344.7 | H15: 739.2 redo, 1138.1 redo again, 641.4 redo again
A16: 15 | B16: 45862 | C16: FGF-SOD-20-3 | D16: =CONCATENATE(ROW(B16)-1,"-",TEXT(B16, "mm-dd-yyyy"),"-",C16) -> 15-07-24-2025-FGF-SOD-20-3 | E16: =SUBSTITUTE(D16,"-","_") -> 15_07_24_2025_FGF_SOD_20_3 | F16: 580.2 | G16: 1153.9 | H16: 554.5 redo, 553.1 redo again
A17: 16 | B17: 46233 | C17: MF-AS-20-1 | D17: =CONCATENATE(ROW(B17)-1,"-",TEXT(B17, "mm-dd-yyyy"),"-",C17) -> 16-07-30-2026-MF-AS-20-1 | E17: =SUBSTITUTE(D17,"-","_") -> 16_07_30_2026_MF_AS_20_1 | F17: 97.8 | G17: 96.6 | H17: 63.2 Upon redo
A18: 17 | B18: 46233 | C18: MF-AS-20-2 | D18: =CONCATENATE(ROW(B18)-1,"-",TEXT(B18, "mm-dd-yyyy"),"-",C18) -> 17-07-30-2026-MF-AS-20-2 | E18: =SUBSTITUTE(D18,"-","_") -> 17_07_30_2026_MF_AS_20_2 | F18: 143 | G18: 275.5
A19: 18 | B19: 46233 | C19: MF-AS-20-3 | D19: =CONCATENATE(ROW(B19)-1,"-",TEXT(B19, "mm-dd-yyyy"),"-",C19) -> 18-07-30-2026-MF-AS-20-3 | E19: =SUBSTITUTE(D19,"-","_") -> 18_07_30_2026_MF_AS_20_3 | F19: 149.8 | G19: 149.3 | H19: 2nd MF-20-2 is this one - got a replicate on accident
A20: 19 | B20: 45862 | C20: FGF-BW-20-1 | D20: =CONCATENATE(ROW(B20)-1,"-",TEXT(B20, "mm-dd-yyyy"),"-",C20) -> 19-07-24-2025-FGF-BW-20-1 | E20: =SUBSTITUTE(D20,"-","_") -> 19_07_24_2025_FGF_BW_20_1 | F20: 207.9 | G20: 284.2
A21: 20 | B21: 45862 | C21: FGF-BW-20-2 | D21: =CONCATENATE(ROW(B21)-1,"-",TEXT(B21, "mm-dd-yyyy"),"-",C21) -> 20-07-24-2025-FGF-BW-20-2 | E21: =SUBSTITUTE(D21,"-","_") -> 20_07_24_2025_FGF_BW_20_2 | F21: 263.6 | G21: 561.2
A22: 21 | B22: 45862 | C22: FGF-BW-20-3 | D22: =CONCATENATE(ROW(B22)-1,"-",TEXT(B22, "mm-dd-yyyy"),"-",C22) -> 21-07-24-2025-FGF-BW-20-3 | E22: =SUBSTITUTE(D22,"-","_") -> 21_07_24_2025_FGF_BW_20_3 | F22: 226.5 | G22: 239.7 | H22: 216.8 upon redo
A23: 22 | B23: 46233 | C23: MF-CH-20-1 | D23: =CONCATENATE(ROW(B23)-1,"-",TEXT(B23, "mm-dd-yyyy"),"-",C23) -> 22-07-30-2026-MF-CH-20-1 | E23: =SUBSTITUTE(D23,"-","_") -> 22_07_30_2026_MF_CH_20_1 | F23: 62.1 | G23: 59.7 | H23: 57.7 redo
A24: 23 | B24: 46233 | C24: MF-CH-20-2 | D24: =CONCATENATE(ROW(B24)-1,"-",TEXT(B24, "mm-dd-yyyy"),"-",C24) -> 23-07-30-2026-MF-CH-20-2 | E24: =SUBSTITUTE(D24,"-","_") -> 23_07_30_2026_MF_CH_20_2 | F24: 101.7 | G24: 140.2
A25: 24 | B25: 46233 | C25: MF-CH-20-3 | D25: =CONCATENATE(ROW(B25)-1,"-",TEXT(B25, "mm-dd-yyyy"),"-",C25) -> 24-07-30-2026-MF-CH-20-3 | E25: =SUBSTITUTE(D25,"-","_") -> 24_07_30_2026_MF_CH_20_3 | F25: 91.2 | G25: 94.2 | H25: Labelled as second MF-CH-20-2
A26: 25 | B26: 46090 | C26: Soy-UD-15-1 | D26: =CONCATENATE(ROW(B26)-1,"-",TEXT(B26, "mm-dd-yyyy"),"-",C26) -> 25-03-09-2026-Soy-UD-15-1 | E26: =SUBSTITUTE(D26,"-","_") -> 25_03_09_2026_Soy_UD_15_1 | F26: 447.4 | G26: 637.3 | H26: Realized here I had not been wiping top mount of nanodrop
A27: 26 | B27: 46090 | C27: Soy-UD-15-2 | D27: =CONCATENATE(ROW(B27)-1,"-",TEXT(B27, "mm-dd-yyyy"),"-",C27) -> 26-03-09-2026-Soy-UD-15-2 | E27: =SUBSTITUTE(D27,"-","_") -> 26_03_09_2026_Soy_UD_15_2 | F27: 574.7 | G27: 564.2
A28: 27 | B28: 46090 | C28: Soy-UD-15-3 | D28: =CONCATENATE(ROW(B28)-1,"-",TEXT(B28, "mm-dd-yyyy"),"-",C28) -> 27-03-09-2026-Soy-UD-15-3 | E28: =SUBSTITUTE(D28,"-","_") -> 27_03_09_2026_Soy_UD_15_3 | F28: 453.1 | G28: 967.6 | H28: 450.8 on redo
A29: 28 | B29: 46090 | C29: Soy-UD-25-1 | D29: =CONCATENATE(ROW(B29)-1,"-",TEXT(B29, "mm-dd-yyyy"),"-",C29) -> 28-03-09-2026-Soy-UD-25-1 | E29: =SUBSTITUTE(D29,"-","_") -> 28_03_09_2026_Soy_UD_25_1 | F29: 461.8 | G29: 730.2
A30: 29 | B30: 46090 | C30: Soy-UD-25-2 | D30: =CONCATENATE(ROW(B30)-1,"-",TEXT(B30, "mm-dd-yyyy"),"-",C30) -> 29-03-09-2026-Soy-UD-25-2 | E30: =SUBSTITUTE(D30,"-","_") -> 29_03_09_2026_Soy_UD_25_2 | F30: 348.2 | G30: 292 | H30: Labelled 25-1
A31: 30 | B31: 46090 | C31: Soy-UD-25-3 | D31: =CONCATENATE(ROW(B31)-1,"-",TEXT(B31, "mm-dd-yyyy"),"-",C31) -> 30-03-09-2026-Soy-UD-25-3 | E31: =SUBSTITUTE(D31,"-","_") -> 30_03_09_2026_Soy_UD_25_3 | F31: 445.5 | G31: 944.5
A32: 31 | B32: 46091 | C32: Soy-C-15-1 | D32: =CONCATENATE(ROW(B32)-1,"-",TEXT(B32, "mm-dd-yyyy"),"-",C32) -> 31-03-10-2026-Soy-C-15-1 | E32: =SUBSTITUTE(D32,"-","_") -> 31_03_10_2026_Soy_C_15_1 | F32: 133.5 | G32: 126.4
A33: 32 | B33: 46091 | C33: Soy-C-15-2 | D33: =CONCATENATE(ROW(B33)-1,"-",TEXT(B33, "mm-dd-yyyy"),"-",C33) -> 32-03-10-2026-Soy-C-15-2 | E33: =SUBSTITUTE(D33,"-","_") -> 32_03_10_2026_Soy_C_15_2 | F33: 207.6 | G33: 245.5
A34: 33 | B34: 46091 | C34: Soy-C-15-3 | D34: =CONCATENATE(ROW(B34)-1,"-",TEXT(B34, "mm-dd-yyyy"),"-",C34) -> 33-03-10-2026-Soy-C-15-3 | E34: =SUBSTITUTE(D34,"-","_") -> 33_03_10_2026_Soy_C_15_3 | F34: 169.4 | G34: 288.1
A35: 34 | B35: 46091 | C35: Soy-C-25-1 | D35: =CONCATENATE(ROW(B35)-1,"-",TEXT(B35, "mm-dd-yyyy"),"-",C35) -> 34-03-10-2026-Soy-C-25-1 | E35: =SUBSTITUTE(D35,"-","_") -> 34_03_10_2026_Soy_C_25_1 | F35: 122.5 | G35: 108.2
A36: 35 | B36: 46091 | C36: Soy-C-25-2 | D36: =CONCATENATE(ROW(B36)-1,"-",TEXT(B36, "mm-dd-yyyy"),"-",C36) -> 35-03-10-2026-Soy-C-25-2 | E36: =SUBSTITUTE(D36,"-","_") -> 35_03_10_2026_Soy_C_25_2 | F36: 173.4 | G36: 452.9
A37: 36 | B37: 46091 | C37: Soy-C-25-3 | D37: =CONCATENATE(ROW(B37)-1,"-",TEXT(B37, "mm-dd-yyyy"),"-",C37) -> 36-03-10-2026-Soy-C-25-3 | E37: =SUBSTITUTE(D37,"-","_") -> 36_03_10_2026_Soy_C_25_3 | F37: 163.3 | G37: 150.9 | H37: 133.9 redo
A38: 37 | B38: 46095 | C38: FGF-OR-15-1 | D38: =CONCATENATE(ROW(B38)-1,"-",TEXT(B38, "mm-dd-yyyy"),"-",C38) -> 37-03-14-2026-FGF-OR-15-1 | E38: =SUBSTITUTE(D38,"-","_") -> 37_03_14_2026_FGF_OR_15_1 | F38: 274.9 | G38: 337.7
A39: 38 | B39: 46095 | C39: FGF-OR-15-2 | D39: =CONCATENATE(ROW(B39)-1,"-",TEXT(B39, "mm-dd-yyyy"),"-",C39) -> 38-03-14-2026-FGF-OR-15-2 | E39: =SUBSTITUTE(D39,"-","_") -> 38_03_14_2026_FGF_OR_15_2 | F39: 245.5 | G39: 314.7
A40: 39 | B40: 46095 | C40: FGF-OR-15-3 | D40: =CONCATENATE(ROW(B40)-1,"-",TEXT(B40, "mm-dd-yyyy"),"-",C40) -> 39-03-14-2026-FGF-OR-15-3 | E40: =SUBSTITUTE(D40,"-","_") -> 39_03_14_2026_FGF_OR_15_3 | F40: 192.7 | G40: 250.4
...

Sheet Soil Samples for Rutgers
A1: Code | B1: Sample Name | C1: Date of Sampling | D1: Samplers | E1: Location Coords | F1: OM%105 | G1: Notes
A2: FGF-ROX-1 6-23-25 | B2: FGF-Rosemary | C2: 45831 | D2: CG,QQ,XZ | G2: Plasticulture
A3: FGF-ORX-1 6-23-25 | B3: FGF-Oregano | C3: 45831 | D3: CG,QQ,XZ | G3: Plasticulture
A4: FGF-YBW-1 6-23-25 | B4: FGF-Buckwheat | C4: 45831 | D4: CG,QQ,XZ | G4: Young
A5: FGF-YBW-2 6-23-25 | B5: FGF-Buckwheat | C5: 45831 | D5: CG,QQ,XZ | G5: Young
A6: FGF-SUN-1 6-23-25 | B6: FGF-Sunflower | C6: 45831 | D6: CG,QQ,XZ
A7: FGF-SUN-2 6-23-25 | B7: FGF-Sunflower | C7: 45831 | D7: CG,QQ,XZ
A8: FGF-YC-1 6-23-25 | B8: FGF-Corn | C8: 45831 | D8: CG,QQ,XZ | G8: Young
A9: FGF-SODX-1 6-23-25 | B9: FGF-Sod | C9: 45831 | D9: CG,QQ,XZ
A10: MOF-CH-1 7-19-25 | B10: MOF-Cherry | C10: 45857 | D10: QQ
A11: MOF-AS-1 7-19-25 | B11: MOF-Asparagus | C11: 45857 | D11: QQ
A12: FGF-OR-1 10-17-25 | B12: FGF-Oregano | C12: 45947 | D12: CG,QQ,EO
A13: FGF-RO-1 10-17-25 | B13: FGF-Rosemary | C13: 45947 | D13: CG,QQ,EO
A14: FGF-OSUN-1 10-17-25 | B14: FGF-Sunflower | C14: 45947 | D14: CG,QQ,EO
A15: FGF-FBW-1 10-17-25 | B15: FGF-Buckwheat | C15: 45947 | D15: CG,QQ,EO | G15: Formerly (mowed)
A16: FGF-CO-1 10-17-25 | B16: FGF-Corn | C16: 45947 | D16: CG,QQ,EO
A17: FGF-SOD-1 10-17-25 | B17: FGF-Sod | C17: 45947 | D17: CG,QQ,EO
A18: SOY-C-1 10-24-25 | B18: Alexander-Rd-Soybean-Center | C18: 45954 | D18: CG,EO
A19: SOY-UD-1 10-24-25 | B19: Alexander-Rd-Soybean-Undisturbed | C19: 45954 | D19: CG,EO
A21: UNTESTED BELOW
B22: Alexander-Rd-Soybean-Edge | C22: 45954 | D22: CG,EO
B23: OFO-Front-Good | C23: 45954 | D23: CG,XZ,FP,EO
B24: OFO-Front-Bad-Empty | C24: 45954 | D24: CG,XZ,FP,EO
B25: OFO-Back-Downhill | C25: 45954 | D25: CG,XZ,FP,EO
B26: OFO-Back-Uphill | C26: 45954 | D26: CG,XZ,FP,EO
B27: OFO-Sod | C27: 45954 | D27: CG,XZ,FP,EO
B28: Seed-Farm-Story-Garden-Old-Corn | C28: 45947 | D28: CG,QQ,EO
B29: Seed-Farm-Story-Garden-Old-Chickpea | C29: 45947 | D29: CG,QQ,EO
B30: Seed-Farm-Lower-Field-Collard-Greens | C30: 45947 | D30: CG,QQ,EO
B31: Seed-Farm-Lower-Field-Winter-Cover-Crop | C31: 45947 | D31: CG,QQ,EO

Sheet Soil Sample Management
A1: Sample Name | B1: Date of Sampling | C1: Samplers | D1: Location Coords | E1: OM%105 | F1: Notes
A2: FGF-Rosemary | B2: 45831 | C2: CG,QQ,XZ | F2: Plasticulture
A3: FGF-Oregano | B3: 45831 | C3: CG,QQ,XZ | F3: Plasticulture
A4: FGF-Buckwheat | B4: 45831 | C4: CG,QQ,XZ | F4: Young
A5: FGF-Sunflower | B5: 45831 | C5: CG,QQ,XZ
A6: FGF-Corn | B6: 45831 | C6: CG,QQ,XZ | F6: Young
A7: FGF-Sod | B7: 45831 | C7: CG,QQ,XZ
A8: MOF-Cherry | B8: 45857 | C8: QQ
A9: MOF-Asparagus | B9: 45857 | C9: QQ
A10: FGF-Oregano | B10: 45947 | C10: CG,QQ,EO
A11: FGF-Rosemary | B11: 45947 | C11: CG,QQ,EO
A12: FGF-Sunflower | B12: 45947 | C12: CG,QQ,EO
A13: FGF-Buckwheat | B13: 45947 | C13: CG,QQ,EO | F13: Formerly (mowed)
A14: FGF-Corn | B14: 45947 | C14: CG,QQ,EO
A15: FGF-Sod | B15: 45947 | C15: CG,QQ,EO
A16: Alexander-Rd-Soybean-Center | B16: 45954 | C16: CG,EO
A17: Alexander-Rd-Soybean-Undisturbed | B17: 45954 | C17: CG,EO
A18: Alexander-Rd-Soybean-Edge | B18: 45954 | C18: CG,EO
A19: OFO-Front-Good | B19: 45954 | C19: CG,XZ,FP,EO
A20: OFO-Front-Bad-Empty | B20: 45954 | C20: CG,XZ,FP,EO
A21: OFO-Back-Downhill | B21: 45954 | C21: CG,XZ,FP,EO
A22: OFO-Back-Uphill | B22: 45954 | C22: CG,XZ,FP,EO
A23: OFO-Sod | B23: 45954 | C23: CG,XZ,FP,EO
A24: Seed-Farm-Story-Garden-Old-Corn | B24: 45947 | C24: CG,QQ,EO
A25: Seed-Farm-Story-Garden-Old-Chickpea | B25: 45947 | C25: CG,QQ,EO
... A27: Seed-Farm-Lower-Field-Winter-Cover-Crop | B27: 45947 | C27: CG,QQ,EO

Sheet H Calibration
A1: Concentration (ppm) | B1: H2 Area | C1: CO Area | D1: Date | E1: Average H2 | F1: STD H2 | G1: Range H2 | H1: Avg CO | I1: STD CO | J1: RF H2 | K1: Range H2
A2: 1.106 | B2: 657692 | C2: 132652 | D2: 46035
A3: 1.106 | B3: 648202 | C3: 110470 | D3: 46035
A4: 1.106 | B4: 665511 | C4: 111721 | D4: 46035
A5: 1.106 | B5: 658318 | C5: 118142 | D5: 46035
A6: 1.106 | B6: 652051 | C6: 113691 | D6: 46035 | E6: =AVERAGE(B2:B6) -> 656354.8 | F6: =_xlfn.STDEV.S(B2:B6) -> 6604.3376 | G6: =MAX(B2:B6)-MIN(B2:B6) -> 17309 | H6: =AVERAGE(C2:C6) -> 117335.2 | I6: =_xlfn.STDEV.S(C2:C6) -> 9044.1375 | J6: =E6/A6 -> 593449.19 | K6: =G6/J6 -> 0.029166777
A7: 1 | B7: 538634 | D7: 46056
A8: 1 | B8: 528844 | D8: 46056
A9: 1 | B9: 543785 | D9: 46056
A10: 1 | B10: 522798 | D10: 46056 | E10: =AVERAGE(B7:B10) -> 533515.25 | F10: =_xlfn.STDEV.S(B7:B10) -> 9457.7903 | G10: =MAX(B7:B10)-MIN(B7:B10) -> 20987 | J10: =E10/A10 -> 533515.25 | K10: =G10/J10 -> 0.039337207
A11: 1.106 | B11: 714044 | D11: 46056
A12: 1.106 | B12: 704231 | D12: 46056
A13: 1.106 | B13: 709233 | D13: 46056
A14: 1.106 | B14: 697764 | D14: 46056
A15: 1.106 | B15: 683599 | D15: 46056 | E15: =AVERAGE(B11:B15) -> 701774.2 | F15: =_xlfn.STDEV.S(B11:B15) -> 11817.753 | G15: =MAX(B11:B15)-MIN(B11:B15) -> 30445 | J15: =E15/A15 -> 634515.55 | K15: =G15/J15 -> 0.047981487

Sheet incomplete 01-28-26 Soy-UD
A1: Identity | B1: Date | C1: Timepoint | D1: Sampling time | E1: H Area | F1: Co Area
A2: Lab Air | B2: 46050 | E2: 249598
A3: Lab Air | B3: 46050 | E3: 251517 | F3: 87039
A4: Lab Air | B4: 46050 | E4: 272055
A5: Lab Air | B5: 46050 | E5: 282520
A6: Lab Air | B6: 46050 | E6: 248387 | F6: 56490
A7: Soy-UD-15-1 | B7: 46050 | C7: 0 | D7: 0.60277778 | E7: 225574
A8: Soy-UD-15-1 | B8: 46050 | C8: 1 | D8: 0.61944444 | E8: 140498
A9: Soy-UD-15-1 | B9: 46050 | C9: 2 | D9: 0.63541667 | E9: 125651
A10: Soy-UD-15-1 | B10: 46050 | C10: 3 | D10: 0.65208333 | E10: 66659
A11: Soy-UD-15-1 | B11: 46050 | C11: 4 | D11: 0.66944444 | E11: 47494
A12: Soy-UD-15-2 | B12: 46050 | C12: 0 | D12: 0.60555556 | E12: 224243
A13: Soy-UD-15-2 | B13: 46050 | C13: 1 | D13: 0.62152778 | E13: 168552
A14: Soy-UD-15-2 | B14: 46050 | C14: 2 | D14: 0.63819444 | E14: 120968
A15: Soy-UD-15-2 | B15: 46050 | C15: 3 | D15: 0.65486111 | E15: 83726
A16: Soy-UD-15-2 | B16: 46050 | C16: 4 | D16: 0.67222222 | E16: 54544
A17: SOY-UD-15-3 | B17: 46050 | C17: 0
A18: SOY-UD-15-3 | B18: 46050 | C18: 1
A19: SOY-UD-15-3 | B19: 46050 | C19: 2
A20: SOY-UD-15-3 | B20: 46050 | C20: 3
A21: SOY-UD-15-3 | B21: 46050 | C21: 4
B22: 46050
B23: 46050
B24: 46050
B25: 46050
B26: 46050
B27: 46050
B28: 46050
B29: 46050
B30: 46050
B31: 46050
B32: 46050
